Workbook

Sheet RESUMEN
A1: RESUMEN GENERAL | J1: ="Fecha de evaluación: "&TEXT(PARAMETROS!$B$9,"DD/MM/YYYY") -> Fecha de evaluación: 08/09/2026
A2: Performance CL | Seguimiento · septiembre 2026
A4: INVERSIÓN | D4: LEADS GENERADOS | G4: EMISIONES / NETOS | J4: VENTAS (solo con meta) | M4: COSTOS
A5: Real corte | B5: =(SUMIFS(DIARIO!$D$2:$D$171,DIARIO!$B$2:$B$171,"MOVIL")+SUMIFS(DIARIO!$D$2:$D$171,DIARIO!$B$2:$B$171,"FIJO")) -> 1.9008375e+08 | D5: Real corte | E5: =(SUMIFS(DIARIO!$E$2:$E$171,DIARIO!$B$2:$B$171,"MOVIL")+SUMIFS(DIARIO!$E$2:$E$171,DIARIO!$B$2:$B$171,"FIJO")) -> 10091 | G5: Real corte | H5: =(SUMIFS(DIARIO!$G$2:$G$171,DIARIO!$B$2:$B$171,"MOVIL")+SUMIFS(DIARIO!$G$2:$G$171,DIARIO!$B$2:$B$171,"FIJO")) -> 4088 | J5: Real corte | K5: =SUMIF($K$14:$K$15,">0",$L$14:$L$15)/PARAMETROS!$B$7 -> 1841 | M5: CPL Meta | N5: =IFERROR((SUMIFS(METAS_DIA!$D$2:$D$541,METAS_DIA!$B$2:$B$541,"MOVIL")+SUMIFS(METAS_DIA!$D$2:$D$541,METAS_DIA!$B$2:$B$541,"FIJO"))/(SUMIFS(METAS_DIA!$E$2:$E$541,METAS_DIA!$B$2:$B$541,"MOVIL")+SUMIFS(METAS_DIA!$E$2:$E$541,METAS_DIA!$B$2:$B$541,"FIJO")),0) -> 11452.902
A6: Meta mes | B6: =(SUMIFS(METAS_DIA!$D$2:$D$541,METAS_DIA!$B$2:$B$541,"MOVIL")+SUMIFS(METAS_DIA!$D$2:$D$541,METAS_DIA!$B$2:$B$541,"FIJO")) -> 6.4402167e+08 | D6: Meta mes | E6: =(SUMIFS(METAS_DIA!$E$2:$E$541,METAS_DIA!$B$2:$B$541,"MOVIL")+SUMIFS(METAS_DIA!$E$2:$E$541,METAS_DIA!$B$2:$B$541,"FIJO")) -> 56232.182 | G6: Meta mes | H6: 0 | J6: Meta mes | K6: =SUMIF($K$14:$K$15,">0",$K$14:$K$15) -> 4372.2521 | M6: CPL Proy. | N6: =IFERROR((SUMIFS(DIARIO!$D$2:$D$171,DIARIO!$B$2:$B$171,"MOVIL")+SUMIFS(DIARIO!$D$2:$D$171,DIARIO!$B$2:$B$171,"FIJO"))/(SUMIFS(DIARIO!$E$2:$E$171,DIARIO!$B$2:$B$171,"MOVIL")+SUMIFS(DIARIO!$E$2:$E$171,DIARIO!$B$2:$B$171,"FIJO")),0) -> 18836.959
A7: Proy. cierre | B7: =(SUMIFS(DIARIO!$D$2:$D$171,DIARIO!$B$2:$B$171,"MOVIL")+SUMIFS(DIARIO!$D$2:$D$171,DIARIO!$B$2:$B$171,"FIJO"))*PARAMETROS!$B$7 -> 7.1281406e+08 | D7: Proy. cierre | E7: =(SUMIFS(DIARIO!$E$2:$E$171,DIARIO!$B$2:$B$171,"MOVIL")+SUMIFS(DIARIO!$E$2:$E$171,DIARIO!$B$2:$B$171,"FIJO"))*PARAMETROS!$B$7 -> 37841.25 | G7: Proy. cierre | H7: =(SUMIFS(DIARIO!$G$2:$G$171,DIARIO!$B$2:$B$171,"MOVIL")+SUMIFS(DIARIO!$G$2:$G$171,DIARIO!$B$2:$B$171,"FIJO"))*PARAMETROS!$B$7 -> 15330 | J7: Proy. cierre | K7: =SUMIF($K$14:$K$15,">0",$L$14:$L$15) -> 6903.75 | M7: CPA Meta | N7: =IFERROR(SUMIF($K$14:$K$15,">0",$B$14:$B$15)/SUMIF($K$14:$K$15,">0",$K$14:$K$15),0) -> 83325.478
A8: Cumpl. proy. | B8: =IFERROR(B7/B6,0) -> 1.1068169 | D8: Cumpl. proy. | E8: =IFERROR(E7/E6,0) -> 0.6729465 | G8: Cumpl. proy. | H8: =IFERROR(H7/H6,0) -> 0 | J8: Cumpl. proy. | K8: =IFERROR(K7/K6,0) -> 1.5789917 | M8: CPA Proy. | N8: =IFERROR(SUMIF($K$14:$K$15,">0",$C$14:$C$15)/SUMIF($K$14:$K$15,">0",$L$14:$L$15),0) -> 48893.03
A11: Cumplimiento por producto
A12: Producto | B12: Presupuesto | E12: Leads | H12: Emitidos | K12: Ventas
B13: Meta | C13: Proy. | D13: % cumpl. | E13: Meta | F13: Proy. | G13: % cumpl. | H13: Meta | I13: Proy. | J13: % cumpl. | K13: Meta | L13: Proy. | M13: % cumpl.
A14: MÓVIL | B14: =SUMIFS(METAS_DIA!$D$2:$D$541,METAS_DIA!$B$2:$B$541,"MOVIL") -> 2.7970167e+08 | C14: =SUMIFS(DIARIO!$D$2:$D$171,DIARIO!$B$2:$B$171,"MOVIL")*PARAMETROS!$B$7 -> 3.752688e+08 | D14: =IFERROR(C14/B14,0) -> 1.3416752 | E14: =SUMIFS(METAS_DIA!$E$2:$E$541,METAS_DIA!$B$2:$B$541,"MOVIL") -> 27412.06 | F14: =SUMIFS(DIARIO!$E$2:$E$171,DIARIO!$B$2:$B$171,"MOVIL")*PARAMETROS!$B$7 -> 20737.5 | G14: =IFERROR(F14/E14,0) -> 0.75651008 | H14: 0 | I14: =SUMIFS(DIARIO!$G$2:$G$171,DIARIO!$B$2:$B$171,"MOVIL")*PARAMETROS!$B$7 -> 6896.25 | J14: =IFERROR(I14/H14,0) -> 0 | K14: =SUMIFS(METAS_DIA!$F$2:$F$541,METAS_DIA!$B$2:$B$541,"MOVIL") -> 0 | L14: =SUMIFS(DIARIO!$H$2:$H$171,DIARIO!$B$2:$B$171,"MOVIL")*PARAMETROS!$B$7 -> 5940 | M14: =IFERROR(L14/K14,0) -> 0
A15: FIJO | B15: =SUMIFS(METAS_DIA!$D$2:$D$541,METAS_DIA!$B$2:$B$541,"FIJO") -> 3.6432e+08 | C15: =SUMIFS(DIARIO!$D$2:$D$171,DIARIO!$B$2:$B$171,"FIJO")*PARAMETROS!$B$7 -> 3.3754526e+08 | D15: =IFERROR(C15/B15,0) -> 0.92650763 | E15: =SUMIFS(METAS_DIA!$E$2:$E$541,METAS_DIA!$B$2:$B$541,"FIJO") -> 28820.121 | F15: =SUMIFS(DIARIO!$E$2:$E$171,DIARIO!$B$2:$B$171,"FIJO")*PARAMETROS!$B$7 -> 17103.75 | G15: =IFERROR(F15/E15,0) -> 0.59346558 | H15: 0 | I15: =SUMIFS(DIARIO!$G$2:$G$171,DIARIO!$B$2:$B$171,"FIJO")*PARAMETROS!$B$7 -> 8433.75 | J15: =IFERROR(I15/H15,0) -> 0 | K15: =SUMIFS(METAS_DIA!$F$2:$F$541,METAS_DIA!$B$2:$B$541,"FIJO") -> 4372.2521 | L15: =SUMIFS(DIARIO!$H$2:$H$171,DIARIO!$B$2:$B$171,"FIJO")*PARAMETROS!$B$7 -> 6903.75 | M15: =IFERROR(L15/K15,0) -> 1.5789917
A16: MIXTO | B16: =SUMIFS(METAS_DIA!$D$2:$D$541,METAS_DIA!$B$2:$B$541,"MIXTO") -> 1.2e+08 | C16: =SUMIFS(DIARIO!$D$2:$D$171,DIARIO!$B$2:$B$171,"MIXTO")*PARAMETROS!$B$7 -> 1.1369478e+08 | D16: =IFERROR(C16/B16,0) -> 0.94745648 | E16: =SUMIFS(METAS_DIA!$E$2:$E$541,METAS_DIA!$B$2:$B$541,"MIXTO") -> 21647.436 | F16: =SUMIFS(DIARIO!$E$2:$E$171,DIARIO!$B$2:$B$171,"MIXTO")*PARAMETROS!$B$7 -> 11055 | G16: =IFERROR(F16/E16,0) -> 0.51068404 | H16: 0 | I16: =SUMIFS(DIARIO!$G$2:$G$171,DIARIO!$B$2:$B$171,"MIXTO")*PARAMETROS!$B$7 -> 3712.5 | J16: =IFERROR(I16/H16,0) -> 0 | K16: =SUMIFS(METAS_DIA!$F$2:$F$541,METAS_DIA!$B$2:$B$541,"MIXTO") -> 0 | L16: =SUMIFS(DIARIO!$H$2:$H$171,DIARIO!$B$2:$B$171,"MIXTO")*PARAMETROS!$B$7 -> 3142.5 | M16: =IFERROR(L16/K16,0) -> 0
A17: TOTAL | B17: =(SUMIFS(METAS_DIA!$D$2:$D$541,METAS_DIA!$B$2:$B$541,"MOVIL")+SUMIFS(METAS_DIA!$D$2:$D$541,METAS_DIA!$B$2:$B$541,"FIJO")) -> 6.4402167e+08 | C17: =(SUMIFS(DIARIO!$D$2:$D$171,DIARIO!$B$2:$B$171,"MOVIL")+SUMIFS(DIARIO!$D$2:$D$171,DIARIO!$B$2:$B$171,"FIJO"))*PARAMETROS!$B$7 -> 7.1281406e+08 | D17: =IFERROR(C17/B17,0) -> 1.1068169 | E17: =(SUMIFS(METAS_DIA!$E$2:$E$541,METAS_DIA!$B$2:$B$541,"MOVIL")+SUMIFS(METAS_DIA!$E$2:$E$541,METAS_DIA!$B$2:$B$541,"FIJO")) -> 56232.182 | F17: =(SUMIFS(DIARIO!$E$2:$E$171,DIARIO!$B$2:$B$171,"MOVIL")+SUMIFS(DIARIO!$E$2:$E$171,DIARIO!$B$2:$B$171,"FIJO"))*PARAMETROS!$B$7 -> 37841.25 | G17: =IFERROR(F17/E17,0) -> 0.6729465 | H17: 0 | I17: =(SUMIFS(DIARIO!$G$2:$G$171,DIARIO!$B$2:$B$171,"MOVIL")+SUMIFS(DIARIO!$G$2:$G$171,DIARIO!$B$2:$B$171,"FIJO"))*PARAMETROS!$B$7 -> 15330 | J17: =IFERROR(I17/H17,0) -> 0 | K17: =SUMIF($K$14:$K$15,">0",$K$14:$K$15) -> 4372.2521 | L17: =SUMIF($K$14:$K$15,">0",$L$14:$L$15) -> 6903.75 | M17: =IFERROR(L17/K17,0) -> 1.5789917
A18: TOTAL = Móvil + Fijo. Mixto no se suma: ya viene repartido dentro de los dos.
A20: Costos
A21: Producto | B21: CPL | E21: CPE | H21: CPA
B22: Meta | C22: Proy. | D22: Var % | E22: Meta | F22: Proy. | G22: Var % | H22: Meta | I22: Proy. | J22: Var %
A23: MÓVIL | B23: =IFERROR(SUMIFS(METAS_DIA!$D$2:$D$541,METAS_DIA!$B$2:$B$541,"MOVIL")/SUMIFS(METAS_DIA!$E$2:$E$541,METAS_DIA!$B$2:$B$541,"MOVIL"),0) -> 10203.599 | C23: =IFERROR(SUMIFS(DIARIO!$D$2:$D$171,DIARIO!$B$2:$B$171,"MOVIL")/SUMIFS(DIARIO!$E$2:$E$171,DIARIO!$B$2:$B$171,"MOVIL"),0) -> 18096.145 | D23: =IFERROR(C23/B23-1,0) -> 0.77350604 | E23: 0 | F23: =IFERROR(SUMIFS(DIARIO!$D$2:$D$171,DIARIO!$B$2:$B$171,"MOVIL")/SUMIFS(DIARIO!$G$2:$G$171,DIARIO!$B$2:$B$171,"MOVIL"),0) -> 54416.357 | G23: =IFERROR(F23/E23-1,0) -> 0 | H23: =IFERROR(SUMIFS(METAS_DIA!$D$2:$D$541,METAS_DIA!$B$2:$B$541,"MOVIL")/SUMIFS(METAS_DIA!$F$2:$F$541,METAS_DIA!$B$2:$B$541,"MOVIL"),0) -> 0 | I23: =IFERROR(SUMIFS(DIARIO!$D$2:$D$171,DIARIO!$B$2:$B$171,"MOVIL")/SUMIFS(DIARIO!$H$2:$H$171,DIARIO!$B$2:$B$171,"MOVIL"),0) -> 63176.566 | J23: =IFERROR(I23/H23-1,0) -> 0
A24: FIJO | B24: =IFERROR(SUMIFS(METAS_DIA!$D$2:$D$541,METAS_DIA!$B$2:$B$541,"FIJO")/SUMIFS(METAS_DIA!$E$2:$E$541,METAS_DIA!$B$2:$B$541,"FIJO"),0) -> 12641.168 | C24: =IFERROR(SUMIFS(DIARIO!$D$2:$D$171,DIARIO!$B$2:$B$171,"FIJO")/SUMIFS(DIARIO!$E$2:$E$171,DIARIO!$B$2:$B$171,"FIJO"),0) -> 19735.161 | D24: =IFERROR(C24/B24-1,0) -> 0.56118175 | E24: 0 | F24: =IFERROR(SUMIFS(DIARIO!$D$2:$D$171,DIARIO!$B$2:$B$171,"FIJO")/SUMIFS(DIARIO!$G$2:$G$171,DIARIO!$B$2:$B$171,"FIJO"),0) -> 40023.152 | G24: =IFERROR(F24/E24-1,0) -> 0 | H24: =IFERROR(SUMIFS(METAS_DIA!$D$2:$D$541,METAS_DIA!$B$2:$B$541,"FIJO")/SUMIFS(METAS_DIA!$F$2:$F$541,METAS_DIA!$B$2:$B$541,"FIJO"),0) -> 83325.478 | I24: =IFERROR(SUMIFS(DIARIO!$D$2:$D$171,DIARIO!$B$2:$B$171,"FIJO")/SUMIFS(DIARIO!$H$2:$H$171,DIARIO!$B$2:$B$171,"FIJO"),0) -> 48893.03 | J24: =IFERROR(I24/H24-1,0) -> -0.41322833
A25: MIXTO | B25: =IFERROR(SUMIFS(METAS_DIA!$D$2:$D$541,METAS_DIA!$B$2:$B$541,"MIXTO")/SUMIFS(METAS_DIA!$E$2:$E$541,METAS_DIA!$B$2:$B$541,"MIXTO"),0) -> 5543.3817 | C25: =IFERROR(SUMIFS(DIARIO!$D$2:$D$171,DIARIO!$B$2:$B$171,"MIXTO")/SUMIFS(DIARIO!$E$2:$E$171,DIARIO!$B$2:$B$171,"MIXTO"),0) -> 10284.467 | D25: =IFERROR(C25/B25-1,0) -> 0.85526942 | E25: 0 | F25: =IFERROR(SUMIFS(DIARIO!$D$2:$D$171,DIARIO!$B$2:$B$171,"MIXTO")/SUMIFS(DIARIO!$G$2:$G$171,DIARIO!$B$2:$B$171,"MIXTO"),0) -> 30624.856 | G25: =IFERROR(F25/E25-1,0) -> 0 | H25: =IFERROR(SUMIFS(METAS_DIA!$D$2:$D$541,METAS_DIA!$B$2:$B$541,"MIXTO")/SUMIFS(METAS_DIA!$F$2:$F$541,METAS_DIA!$B$2:$B$541,"MIXTO"),0) -> 0 | I25: =IFERROR(SUMIFS(DIARIO!$D$2:$D$171,DIARIO!$B$2:$B$171,"MIXTO")/SUMIFS(DIARIO!$H$2:$H$171,DIARIO!$B$2:$B$171,"MIXTO"),0) -> 36179.722 | J25: =IFERROR(I25/H25-1,0) -> 0
A26: TOTAL | B26: =IFERROR((SUMIFS(METAS_DIA!$D$2:$D$541,METAS_DIA!$B$2:$B$541,"MOVIL")+SUMIFS(METAS_DIA!$D$2:$D$541,METAS_DIA!$B$2:$B$541,"FIJO"))/(SUMIFS(METAS_DIA!$E$2:$E$541,METAS_DIA!$B$2:$B$541,"MOVIL")+SUMIFS(METAS_DIA!$E$2:$E$541,METAS_DIA!$B$2:$B$541,"FIJO")),0) -> 11452.902 | C26: =IFERROR((SUMIFS(DIARIO!$D$2:$D$171,DIARIO!$B$2:$B$171,"MOVIL")+SUMIFS(DIARIO!$D$2:$D$171,DIARIO!$B$2:$B$171,"FIJO"))/(SUMIFS(DIARIO!$E$2:$E$171,DIARIO!$B$2:$B$171,"MOVIL")+SUMIFS(DIARIO!$E$2:$E$171,DIARIO!$B$2:$B$171,"FIJO")),0) -> 18836.959 | D26: =IFERROR(C26/B26-1,0) -> 0.64473234 | E26: 0 | F26: =IFERROR((SUMIFS(DIARIO!$D$2:$D$171,DIARIO!$B$2:$B$171,"MOVIL")+SUMIFS(DIARIO!$D$2:$D$171,DIARIO!$B$2:$B$171,"FIJO"))/(SUMIFS(DIARIO!$G$2:$G$171,DIARIO!$B$2:$B$171,"MOVIL")+SUMIFS(DIARIO!$G$2:$G$171,DIARIO!$B$2:$B$171,"FIJO")),0) -> 46497.982 | G26: =IFERROR(F26/E26-1,0) -> 0 | H26: =IFERROR(SUMIF($K$14:$K$15,">0",$B$14:$B$15)/SUMIF($K$14:$K$15,">0",$K$14:$K$15),0) -> 83325.478 | I26: =IFERROR(SUMIF($K$14:$K$15,">0",$C$14:$C$15)/SUMIF($K$14:$K$15,">0",$L$14:$L$15),0) -> 48893.03 | J26: =IFERROR(I26/H26-1,0) -> -0.41322833
A28: Emisiones y CPE no tienen meta en el presupuesto: quedan en 0 a propósito. La meta de ventas solo viene cargada para Fijo, así que la tarjeta de VENTAS y el CPA del TOTAL se calculan únicamente sobre los bloques que sí tienen meta.

Sheet MAQUETA
A1: TRACKING Y PROYECCION A CIERRE · 2026-09
A2: Proyeccion = Real acumulado / dias con informacion x dias del mes (run-rate simple). 'Meta a hoy' es la meta diaria acumulada hasta la fecha de corte, para ver el pacing. Parametros en PARAMETROS.
A4: COSTOS MOVIL | H4: LEADS MOVIL | O4: CPL MOVIL
A5: Canal 2 | B5: Meta Costo mes | C5: Meta a hoy | D5: Real Costo | E5: % a hoy | F5: Costo proyectado | H5: Canal 2 | I5: Meta Leads mes | J5: Meta a hoy | K5: Real Leads | L5: % a hoy | M5: Leads Proyectados | O5: Canal 2 | P5: CPL Meta | Q5: CPL | R5: % Cumplimiento
A6: Afiliados | B6: =SUMIFS(METAS_DIA!$D$2:$D$541,METAS_DIA!$B$2:$B$541,"MOVIL",METAS_DIA!$C$2:$C$541,$A6) -> 0 | C6: =SUMIFS(METAS_DIA!$D$2:$D$541,METAS_DIA!$B$2:$B$541,"MOVIL",METAS_DIA!$C$2:$C$541,$A6,METAS_DIA!$A$2:$A$541,"<="&PARAMETROS!$B$9) -> 0 | D6: =SUMIFS(DIARIO!$D$2:$D$171,DIARIO!$B$2:$B$171,"MOVIL",DIARIO!$C$2:$C$171,$A6) -> 0 | E6: =IFERROR(D6/C6,0) -> 0 | F6: =D6*PARAMETROS!$B$7 -> 0 | H6: Afiliados | I6: =SUMIFS(METAS_DIA!$E$2:$E$541,METAS_DIA!$B$2:$B$541,"MOVIL",METAS_DIA!$C$2:$C$541,$H6) -> 0 | J6: =SUMIFS(METAS_DIA!$E$2:$E$541,METAS_DIA!$B$2:$B$541,"MOVIL",METAS_DIA!$C$2:$C$541,$H6,METAS_DIA!$A$2:$A$541,"<="&PARAMETROS!$B$9) -> 0 | K6: =SUMIFS(DIARIO!$E$2:$E$171,DIARIO!$B$2:$B$171,"MOVIL",DIARIO!$C$2:$C$171,$H6) -> 0 | L6: =IFERROR(K6/J6,0) -> 0 | M6: =K6*PARAMETROS!$B$7 -> 0 | O6: Afiliados | P6: =IFERROR(B6/I6,0) -> 0 | Q6: =IFERROR(D6/K6,0) -> 0 | R6: =IFERROR(Q6/P6,0) -> 0
A7: Bing | B7: =SUMIFS(METAS_DIA!$D$2:$D$541,METAS_DIA!$B$2:$B$541,"MOVIL",METAS_DIA!$C$2:$C$541,$A7) -> 5000000 | C7: =SUMIFS(METAS_DIA!$D$2:$D$541,METAS_DIA!$B$2:$B$541,"MOVIL",METAS_DIA!$C$2:$C$541,$A7,METAS_DIA!$A$2:$A$541,"<="&PARAMETROS!$B$9) -> 1465601.6 | D7: =SUMIFS(DIARIO!$D$2:$D$171,DIARIO!$B$2:$B$171,"MOVIL",DIARIO!$C$2:$C$171,$A7) -> 376322.91 | E7: =IFERROR(D7/C7,0) -> 0.25677027 | F7: =D7*PARAMETROS!$B$7 -> 1411210.9 | H7: Bing | I7: =SUMIFS(METAS_DIA!$E$2:$E$541,METAS_DIA!$B$2:$B$541,"MOVIL",METAS_DIA!$C$2:$C$541,$H7) -> 714.28571 | J7: =SUMIFS(METAS_DIA!$E$2:$E$541,METAS_DIA!$B$2:$B$541,"MOVIL",METAS_DIA!$C$2:$C$541,$H7,METAS_DIA!$A$2:$A$541,"<="&PARAMETROS!$B$9) -> 209.37165 | K7: =SUMIFS(DIARIO!$E$2:$E$171,DIARIO!$B$2:$B$171,"MOVIL",DIARIO!$C$2:$C$171,$H7) -> 32 | L7: =IFERROR(K7/J7,0) -> 0.15283826 | M7: =K7*PARAMETROS!$B$7 -> 120 | O7: Bing | P7: =IFERROR(B7/I7,0) -> 7000 | Q7: =IFERROR(D7/K7,0) -> 11760.091 | R7: =IFERROR(Q7/P7,0) -> 1.680013
A8: Bing Mixto | B8: =SUMIFS(METAS_DIA!$D$2:$D$541,METAS_DIA!$B$2:$B$541,"MOVIL",METAS_DIA!$C$2:$C$541,$A8) -> 1000000 | C8: =SUMIFS(METAS_DIA!$D$2:$D$541,METAS_DIA!$B$2:$B$541,"MOVIL",METAS_DIA!$C$2:$C$541,$A8,METAS_DIA!$A$2:$A$541,"<="&PARAMETROS!$B$9) -> 296000.09 | D8: =SUMIFS(DIARIO!$D$2:$D$171,DIARIO!$B$2:$B$171,"MOVIL",DIARIO!$C$2:$C$171,$A8) -> 295353.35 | E8: =IFERROR(D8/C8,0) -> 0.99781506 | F8: =D8*PARAMETROS!$B$7 -> 1107575 | H8: Bing Mixto | I8: =SUMIFS(METAS_DIA!$E$2:$E$541,METAS_DIA!$B$2:$B$541,"MOVIL",METAS_DIA!$C$2:$C$541,$H8) -> 83.333333 | J8: =SUMIFS(METAS_DIA!$E$2:$E$541,METAS_DIA!$B$2:$B$541,"MOVIL",METAS_DIA!$C$2:$C$541,$H8,METAS_DIA!$A$2:$A$541,"<="&PARAMETROS!$B$9) -> 24.666674 | K8: =SUMIFS(DIARIO!$E$2:$E$171,DIARIO!$B$2:$B$171,"MOVIL",DIARIO!$C$2:$C$171,$H8) -> 147.5 | L8: =IFERROR(K8/J8,0) -> 5.979728 | M8: =K8*PARAMETROS!$B$7 -> 553.125 | O8: Bing Mixto | P8: =IFERROR(B8/I8,0) -> 12000 | Q8: =IFERROR(D8/K8,0) -> 2002.3956 | R8: =IFERROR(Q8/P8,0) -> 0.1668663
A9: Display | B9: =SUMIFS(METAS_DIA!$D$2:$D$541,METAS_DIA!$B$2:$B$541,"MOVIL",METAS_DIA!$C$2:$C$541,$A9) -> 5000000 | C9: =SUMIFS(METAS_DIA!$D$2:$D$541,METAS_DIA!$B$2:$B$541,"MOVIL",METAS_DIA!$C$2:$C$541,$A9,METAS_DIA!$A$2:$A$541,"<="&PARAMETROS!$B$9) -> 1465601.6 | D9: =SUMIFS(DIARIO!$D$2:$D$171,DIARIO!$B$2:$B$171,"MOVIL",DIARIO!$C$2:$C$171,$A9) -> 0 | E9: =IFERROR(D9/C9,0) -> 0 | F9: =D9*PARAMETROS!$B$7 -> 0 | H9: Display | I9: =SUMIFS(METAS_DIA!$E$2:$E$541,METAS_DIA!$B$2:$B$541,"MOVIL",METAS_DIA!$C$2:$C$541,$H9) -> 684.65014 | J9: =SUMIFS(METAS_DIA!$E$2:$E$541,METAS_DIA!$B$2:$B$541,"MOVIL",METAS_DIA!$C$2:$C$541,$H9,METAS_DIA!$A$2:$A$541,"<="&PARAMETROS!$B$9) -> 200.68486 | K9: =SUMIFS(DIARIO!$E$2:$E$171,DIARIO!$B$2:$B$171,"MOVIL",DIARIO!$C$2:$C$171,$H9) -> 0 | L9: =IFERROR(K9/J9,0) -> 0 | M9: =K9*PARAMETROS!$B$7 -> 0 | O9: Display | P9: =IFERROR(B9/I9,0) -> 7303 | Q9: =IFERROR(D9/K9,0) -> 0 | R9: =IFERROR(Q9/P9,0) -> 0
A10: Meta | B10: =SUMIFS(METAS_DIA!$D$2:$D$541,METAS_DIA!$B$2:$B$541,"MOVIL",METAS_DIA!$C$2:$C$541,$A10) -> 20000000 | C10: =SUMIFS(METAS_DIA!$D$2:$D$541,METAS_DIA!$B$2:$B$541,"MOVIL",METAS_DIA!$C$2:$C$541,$A10,METAS_DIA!$A$2:$A$541,"<="&PARAMETROS!$B$9) -> 5862406.3 | D10: =SUMIFS(DIARIO!$D$2:$D$171,DIARIO!$B$2:$B$171,"MOVIL",DIARIO!$C$2:$C$171,$A10) -> 6256117.9 | E10: =IFERROR(D10/C10,0) -> 1.0671587 | F10: =D10*PARAMETROS!$B$7 -> 23460442 | H10: Meta | I10: =SUMIFS(METAS_DIA!$E$2:$E$541,METAS_DIA!$B$2:$B$541,"MOVIL",METAS_DIA!$C$2:$C$541,$H10) -> 2777.7778 | J10: =SUMIFS(METAS_DIA!$E$2:$E$541,METAS_DIA!$B$2:$B$541,"MOVIL",METAS_DIA!$C$2:$C$541,$H10,METAS_DIA!$A$2:$A$541,"<="&PARAMETROS!$B$9) -> 814.22309 | K10: =SUMIFS(DIARIO!$E$2:$E$171,DIARIO!$B$2:$B$171,"MOVIL",DIARIO!$C$2:$C$171,$H10) -> 1039 | L10: =IFERROR(K10/J10,0) -> 1.276063 | M10: =K10*PARAMETROS!$B$7 -> 3896.25 | O10: Meta | P10: =IFERROR(B10/I10,0) -> 7200 | Q10: =IFERROR(D10/K10,0) -> 6021.2876 | R10: =IFERROR(Q10/P10,0) -> 0.83628995
A11: Pmax | B11: =SUMIFS(METAS_DIA!$D$2:$D$541,METAS_DIA!$B$2:$B$541,"MOVIL",METAS_DIA!$C$2:$C$541,$A11) -> 25000000 | C11: =SUMIFS(METAS_DIA!$D$2:$D$541,METAS_DIA!$B$2:$B$541,"MOVIL",METAS_DIA!$C$2:$C$541,$A11,METAS_DIA!$A$2:$A$541,"<="&PARAMETROS!$B$9) -> 7328007.8 | D11: =SUMIFS(DIARIO!$D$2:$D$171,DIARIO!$B$2:$B$171,"MOVIL",DIARIO!$C$2:$C$171,$A11) -> 4554627.5 | E11: =IFERROR(D11/C11,0) -> 0.62153693 | F11: =D11*PARAMETROS!$B$7 -> 17079853 | H11: Pmax | I11: =SUMIFS(METAS_DIA!$E$2:$E$541,METAS_DIA!$B$2:$B$541,"MOVIL",METAS_DIA!$C$2:$C$541,$H11) -> 1785.7143 | J11: =SUMIFS(METAS_DIA!$E$2:$E$541,METAS_DIA!$B$2:$B$541,"MOVIL",METAS_DIA!$C$2:$C$541,$H11,METAS_DIA!$A$2:$A$541,"<="&PARAMETROS!$B$9) -> 523.42913 | K11: =SUMIFS(DIARIO!$E$2:$E$171,DIARIO!$B$2:$B$171,"MOVIL",DIARIO!$C$2:$C$171,$H11) -> 233 | L11: =IFERROR(K11/J11,0) -> 0.44514145 | M11: =K11*PARAMETROS!$B$7 -> 873.75 | O11: Pmax | P11: =IFERROR(B11/I11,0) -> 14000 | Q11: =IFERROR(D11/K11,0) -> 19547.757 | R11: =IFERROR(Q11/P11,0) -> 1.3962684
A12: Pmax Mixto | B12: =SUMIFS(METAS_DIA!$D$2:$D$541,METAS_DIA!$B$2:$B$541,"MOVIL",METAS_DIA!$C$2:$C$541,$A12) -> 9000000 | C12: =SUMIFS(METAS_DIA!$D$2:$D$541,METAS_DIA!$B$2:$B$541,"MOVIL",METAS_DIA!$C$2:$C$541,$A12,METAS_DIA!$A$2:$A$541,"<="&PARAMETROS!$B$9) -> 2664000.8 | D12: =SUMIFS(DIARIO!$D$2:$D$171,DIARIO!$B$2:$B$171,"MOVIL",DIARIO!$C$2:$C$171,$A12) -> 5044319.2 | E12: =IFERROR(D12/C12,0) -> 1.8935126 | F12: =D12*PARAMETROS!$B$7 -> 18916197 | H12: Pmax Mixto | I12: =SUMIFS(METAS_DIA!$E$2:$E$541,METAS_DIA!$B$2:$B$541,"MOVIL",METAS_DIA!$C$2:$C$541,$H12) -> 1125 | J12: =SUMIFS(METAS_DIA!$E$2:$E$541,METAS_DIA!$B$2:$B$541,"MOVIL",METAS_DIA!$C$2:$C$541,$H12,METAS_DIA!$A$2:$A$541,"<="&PARAMETROS!$B$9) -> 333.0001 | K12: =SUMIFS(DIARIO!$E$2:$E$171,DIARIO!$B$2:$B$171,"MOVIL",DIARIO!$C$2:$C$171,$H12) -> 302 | L12: =IFERROR(K12/J12,0) -> 0.90690664 | M12: =K12*PARAMETROS!$B$7 -> 1132.5 | O12: Pmax Mixto | P12: =IFERROR(B12/I12,0) -> 8000 | Q12: =IFERROR(D12/K12,0) -> 16703.044 | R12: =IFERROR(Q12/P12,0) -> 2.0878804
A13: Search | B13: =SUMIFS(METAS_DIA!$D$2:$D$541,METAS_DIA!$B$2:$B$541,"MOVIL",METAS_DIA!$C$2:$C$541,$A13) -> 1.6470167e+08 | C13: =SUMIFS(METAS_DIA!$D$2:$D$541,METAS_DIA!$B$2:$B$541,"MOVIL",METAS_DIA!$C$2:$C$541,$A13,METAS_DIA!$A$2:$A$541,"<="&PARAMETROS!$B$9) -> 48277406 | D13: =SUMIFS(DIARIO!$D$2:$D$171,DIARIO!$B$2:$B$171,"MOVIL",DIARIO!$C$2:$C$171,$A13) -> 73725308 | E13: =IFERROR(D13/C13,0) -> 1.5271182 | F13: =D13*PARAMETROS!$B$7 -> 2.7646991e+08 | H13: Search | I13: =SUMIFS(METAS_DIA!$E$2:$E$541,METAS_DIA!$B$2:$B$541,"MOVIL",METAS_DIA!$C$2:$C$541,$H13) -> 10625.914 | J13: =SUMIFS(METAS_DIA!$E$2:$E$541,METAS_DIA!$B$2:$B$541,"MOVIL",METAS_DIA!$C$2:$C$541,$H13,METAS_DIA!$A$2:$A$541,"<="&PARAMETROS!$B$9) -> 3114.6714 | K13: =SUMIFS(DIARIO!$E$2:$E$171,DIARIO!$B$2:$B$171,"MOVIL",DIARIO!$C$2:$C$171,$H13) -> 2752 | L13: =IFERROR(K13/J13,0) -> 0.88356031 | M13: =K13*PARAMETROS!$B$7 -> 10320 | O13: Search | P13: =IFERROR(B13/I13,0) -> 15500 | Q13: =IFERROR(D13/K13,0) -> 26789.719 | R13: =IFERROR(Q13/P13,0) -> 1.728369
A14: Search Mixto | B14: =SUMIFS(METAS_DIA!$D$2:$D$541,METAS_DIA!$B$2:$B$541,"MOVIL",METAS_DIA!$C$2:$C$541,$A14) -> 50000000 | C14: =SUMIFS(METAS_DIA!$D$2:$D$541,METAS_DIA!$B$2:$B$541,"MOVIL",METAS_DIA!$C$2:$C$541,$A14,METAS_DIA!$A$2:$A$541,"<="&PARAMETROS!$B$9) -> 14800004 | D14: =SUMIFS(DIARIO!$D$2:$D$171,DIARIO!$B$2:$B$171,"MOVIL",DIARIO!$C$2:$C$171,$A14) -> 9819631.2 | E14: =IFERROR(D14/C14,0) -> 0.6634884 | F14: =D14*PARAMETROS!$B$7 -> 36823617 | H14: Search Mixto | I14: =SUMIFS(METAS_DIA!$E$2:$E$541,METAS_DIA!$B$2:$B$541,"MOVIL",METAS_DIA!$C$2:$C$541,$H14) -> 9615.3846 | J14: =SUMIFS(METAS_DIA!$E$2:$E$541,METAS_DIA!$B$2:$B$541,"MOVIL",METAS_DIA!$C$2:$C$541,$H14,METAS_DIA!$A$2:$A$541,"<="&PARAMETROS!$B$9) -> 2846.1547 | K14: =SUMIFS(DIARIO!$E$2:$E$171,DIARIO!$B$2:$B$171,"MOVIL",DIARIO!$C$2:$C$171,$H14) -> 1024.5 | L14: =IFERROR(K14/J14,0) -> 0.35995935 | M14: =K14*PARAMETROS!$B$7 -> 3841.875 | O14: Search Mixto | P14: =IFERROR(B14/I14,0) -> 5200 | Q14: =IFERROR(D14/K14,0) -> 9584.8035 | R14: =IFERROR(Q14/P14,0) -> 1.8432314
A15: TikTok | B15: =SUMIFS(METAS_DIA!$D$2:$D$541,METAS_DIA!$B$2:$B$541,"MOVIL",METAS_DIA!$C$2:$C$541,$A15) -> 0 | C15: =SUMIFS(METAS_DIA!$D$2:$D$541,METAS_DIA!$B$2:$B$541,"MOVIL",METAS_DIA!$C$2:$C$541,$A15,METAS_DIA!$A$2:$A$541,"<="&PARAMETROS!$B$9) -> 0 | D15: =SUMIFS(DIARIO!$D$2:$D$171,DIARIO!$B$2:$B$171,"MOVIL",DIARIO!$C$2:$C$171,$A15) -> 0 | E15: =IFERROR(D15/C15,0) -> 0 | F15: =D15*PARAMETROS!$B$7 -> 0 | H15: TikTok | I15: =SUMIFS(METAS_DIA!$E$2:$E$541,METAS_DIA!$B$2:$B$541,"MOVIL",METAS_DIA!$C$2:$C$541,$H15) -> 0 | J15: =SUMIFS(METAS_DIA!$E$2:$E$541,METAS_DIA!$B$2:$B$541,"MOVIL",METAS_DIA!$C$2:$C$541,$H15,METAS_DIA!$A$2:$A$541,"<="&PARAMETROS!$B$9) -> 0 | K15: =SUMIFS(DIARIO!$E$2:$E$171,DIARIO!$B$2:$B$171,"MOVIL",DIARIO!$C$2:$C$171,$H15) -> 0 | L15: =IFERROR(K15/J15,0) -> 0 | M15: =K15*PARAMETROS!$B$7 -> 0 | O15: TikTok | P15: =IFERROR(B15/I15,0) -> 0 | Q15: =IFERROR(D15/K15,0) -> 0 | R15: =IFERROR(Q15/P15,0) -> 0
A16: Total | B16: =SUM(B6:B15) -> 2.7970167e+08 | C16: =SUM(C6:C15) -> 82159029 | D16: =SUM(D6:D15) -> 1.0007168e+08 | E16: =IFERROR(D16/C16,0) -> 1.2180241 | F16: =SUM(F6:F15) -> 3.752688e+08 | H16: Total | I16: =SUM(I6:I15) -> 27412.06 | J16: =SUM(J6:J15) -> 8066.2016 | K16: =SUM(K6:K15) -> 5530 | L16: =IFERROR(K16/J16,0) -> 0.68557672 | M16: =SUM(M6:M15) -> 20737.5 | O16: Total | P16: =IFERROR(B16/I16,0) -> 10203.599 | Q16: =IFERROR(D16/K16,0) -> 18096.145 | R16: =IFERROR(Q16/P16,0) -> 1.773506
A18: EMBUDO Y COSTOS UNITARIOS MOVIL · sin meta asociada
A19: Canal 2 | B19: Q Neto | C19: Q Neto proy | D19: CPL Neto | E19: Q Emi | F19: Q Emi proy | G19: CPE | H19: Q Ter | I19: Q Ter proy | J19: CPA
A20: Afiliados | B20: =SUMIFS(DIARIO!$F$2:$F$171,DIARIO!$B$2:$B$171,"MOVIL",DIARIO!$C$2:$C$171,$A20) -> 468 | C20: =B20*PARAMETROS!$B$7 -> 1755 | D20: =IFERROR(SUMIFS(DIARIO!$D$2:$D$171,DIARIO!$B$2:$B$171,"MOVIL",DIARIO!$C$2:$C$171,$A20)/B20,0) -> 0 | E20: =SUMIFS(DIARIO!$G$2:$G$171,DIARIO!$B$2:$B$171,"MOVIL",DIARIO!$C$2:$C$171,$A20) -> 251 | F20: =E20*PARAMETROS!$B$7 -> 941.25 | G20: =IFERROR(SUMIFS(DIARIO!$D$2:$D$171,DIARIO!$B$2:$B$171,"MOVIL",DIARIO!$C$2:$C$171,$A20)/E20,0) -> 0 | H20: =SUMIFS(DIARIO!$H$2:$H$171,DIARIO!$B$2:$B$171,"MOVIL",DIARIO!$C$2:$C$171,$A20) -> 207 | I20: =H20*PARAMETROS!$B$7 -> 776.25 | J20: =IFERROR(SUMIFS(DIARIO!$D$2:$D$171,DIARIO!$B$2:$B$171,"MOVIL",DIARIO!$C$2:$C$171,$A20)/H20,0) -> 0
A21: Bing | B21: =SUMIFS(DIARIO!$F$2:$F$171,DIARIO!$B$2:$B$171,"MOVIL",DIARIO!$C$2:$C$171,$A21) -> 23 | C21: =B21*PARAMETROS!$B$7 -> 86.25 | D21: =IFERROR(SUMIFS(DIARIO!$D$2:$D$171,DIARIO!$B$2:$B$171,"MOVIL",DIARIO!$C$2:$C$171,$A21)/B21,0) -> 16361.866 | E21: =SUMIFS(DIARIO!$G$2:$G$171,DIARIO!$B$2:$B$171,"MOVIL",DIARIO!$C$2:$C$171,$A21) -> 19 | F21: =E21*PARAMETROS!$B$7 -> 71.25 | G21: =IFERROR(SUMIFS(DIARIO!$D$2:$D$171,DIARIO!$B$2:$B$171,"MOVIL",DIARIO!$C$2:$C$171,$A21)/E21,0) -> 19806.469 | H21: =SUMIFS(DIARIO!$H$2:$H$171,DIARIO!$B$2:$B$171,"MOVIL",DIARIO!$C$2:$C$171,$A21) -> 15 | I21: =H21*PARAMETROS!$B$7 -> 56.25 | J21: =IFERROR(SUMIFS(DIARIO!$D$2:$D$171,DIARIO!$B$2:$B$171,"MOVIL",DIARIO!$C$2:$C$171,$A21)/H21,0) -> 25088.194
A22: Bing Mixto | B22: =SUMIFS(DIARIO!$F$2:$F$171,DIARIO!$B$2:$B$171,"MOVIL",DIARIO!$C$2:$C$171,$A22) -> 59 | C22: =B22*PARAMETROS!$B$7 -> 221.25 | D22: =IFERROR(SUMIFS(DIARIO!$D$2:$D$171,DIARIO!$B$2:$B$171,"MOVIL",DIARIO!$C$2:$C$171,$A22)/B22,0) -> 5005.9889 | E22: =SUMIFS(DIARIO!$G$2:$G$171,DIARIO!$B$2:$B$171,"MOVIL",DIARIO!$C$2:$C$171,$A22) -> 31.5 | F22: =E22*PARAMETROS!$B$7 -> 118.125 | G22: =IFERROR(SUMIFS(DIARIO!$D$2:$D$171,DIARIO!$B$2:$B$171,"MOVIL",DIARIO!$C$2:$C$171,$A22)/E22,0) -> 9376.2967 | H22: =SUMIFS(DIARIO!$H$2:$H$171,DIARIO!$B$2:$B$171,"MOVIL",DIARIO!$C$2:$C$171,$A22) -> 22 | I22: =H22*PARAMETROS!$B$7 -> 82.5 | J22: =IFERROR(SUMIFS(DIARIO!$D$2:$D$171,DIARIO!$B$2:$B$171,"MOVIL",DIARIO!$C$2:$C$171,$A22)/H22,0) -> 13425.152
A23: Display | B23: =SUMIFS(DIARIO!$F$2:$F$171,DIARIO!$B$2:$B$171,"MOVIL",DIARIO!$C$2:$C$171,$A23) -> 0 | C23: =B23*PARAMETROS!$B$7 -> 0 | D23: =IFERROR(SUMIFS(DIARIO!$D$2:$D$171,DIARIO!$B$2:$B$171,"MOVIL",DIARIO!$C$2:$C$171,$A23)/B23,0) -> 0 | E23: =SUMIFS(DIARIO!$G$2:$G$171,DIARIO!$B$2:$B$171,"MOVIL",DIARIO!$C$2:$C$171,$A23) -> 0 | F23: =E23*PARAMETROS!$B$7 -> 0 | G23: =IFERROR(SUMIFS(DIARIO!$D$2:$D$171,DIARIO!$B$2:$B$171,"MOVIL",DIARIO!$C$2:$C$171,$A23)/E23,0) -> 0 | H23: =SUMIFS(DIARIO!$H$2:$H$171,DIARIO!$B$2:$B$171,"MOVIL",DIARIO!$C$2:$C$171,$A23) -> 0 | I23: =H23*PARAMETROS!$B$7 -> 0 | J23: =IFERROR(SUMIFS(DIARIO!$D$2:$D$171,DIARIO!$B$2:$B$171,"MOVIL",DIARIO!$C$2:$C$171,$A23)/H23,0) -> 0
A24: Meta | B24: =SUMIFS(DIARIO!$F$2:$F$171,DIARIO!$B$2:$B$171,"MOVIL",DIARIO!$C$2:$C$171,$A24) -> 671 | C24: =B24*PARAMETROS!$B$7 -> 2516.25 | D24: =IFERROR(SUMIFS(DIARIO!$D$2:$D$171,DIARIO!$B$2:$B$171,"MOVIL",DIARIO!$C$2:$C$171,$A24)/B24,0) -> 9323.5736 | E24: =SUMIFS(DIARIO!$G$2:$G$171,DIARIO!$B$2:$B$171,"MOVIL",DIARIO!$C$2:$C$171,$A24) -> 132 | F24: =E24*PARAMETROS!$B$7 -> 495 | G24: =IFERROR(SUMIFS(DIARIO!$D$2:$D$171,DIARIO!$B$2:$B$171,"MOVIL",DIARIO!$C$2:$C$171,$A24)/E24,0) -> 47394.832 | H24: =SUMIFS(DIARIO!$H$2:$H$171,DIARIO!$B$2:$B$171,"MOVIL",DIARIO!$C$2:$C$171,$A24) -> 92 | I24: =H24*PARAMETROS!$B$7 -> 345 | J24: =IFERROR(SUMIFS(DIARIO!$D$2:$D$171,DIARIO!$B$2:$B$171,"MOVIL",DIARIO!$C$2:$C$171,$A24)/H24,0) -> 68001.281
A25: Pmax | B25: =SUMIFS(DIARIO!$F$2:$F$171,DIARIO!$B$2:$B$171,"MOVIL",DIARIO!$C$2:$C$171,$A25) -> 145 | C25: =B25*PARAMETROS!$B$7 -> 543.75 | D25: =IFERROR(SUMIFS(DIARIO!$D$2:$D$171,DIARIO!$B$2:$B$171,"MOVIL",DIARIO!$C$2:$C$171,$A25)/B25,0) -> 31411.224 | E25: =SUMIFS(DIARIO!$G$2:$G$171,DIARIO!$B$2:$B$171,"MOVIL",DIARIO!$C$2:$C$171,$A25) -> 64 | F25: =E25*PARAMETROS!$B$7 -> 240 | G25: =IFERROR(SUMIFS(DIARIO!$D$2:$D$171,DIARIO!$B$2:$B$171,"MOVIL",DIARIO!$C$2:$C$171,$A25)/E25,0) -> 71166.054 | H25: =SUMIFS(DIARIO!$H$2:$H$171,DIARIO!$B$2:$B$171,"MOVIL",DIARIO!$C$2:$C$171,$A25) -> 53 | I25: =H25*PARAMETROS!$B$7 -> 198.75 | J25: =IFERROR(SUMIFS(DIARIO!$D$2:$D$171,DIARIO!$B$2:$B$171,"MOVIL",DIARIO!$C$2:$C$171,$A25)/H25,0) -> 85936.368
A26: Pmax Mixto | B26: =SUMIFS(DIARIO!$F$2:$F$171,DIARIO!$B$2:$B$171,"MOVIL",DIARIO!$C$2:$C$171,$A26) -> 198.5 | C26: =B26*PARAMETROS!$B$7 -> 744.375 | D26: =IFERROR(SUMIFS(DIARIO!$D$2:$D$171,DIARIO!$B$2:$B$171,"MOVIL",DIARIO!$C$2:$C$171,$A26)/B26,0) -> 25412.187 | E26: =SUMIFS(DIARIO!$G$2:$G$171,DIARIO!$B$2:$B$171,"MOVIL",DIARIO!$C$2:$C$171,$A26) -> 71 | F26: =E26*PARAMETROS!$B$7 -> 266.25 | G26: =IFERROR(SUMIFS(DIARIO!$D$2:$D$171,DIARIO!$B$2:$B$171,"MOVIL",DIARIO!$C$2:$C$171,$A26)/E26,0) -> 71046.749 | H26: =SUMIFS(DIARIO!$H$2:$H$171,DIARIO!$B$2:$B$171,"MOVIL",DIARIO!$C$2:$C$171,$A26) -> 48 | I26: =H26*PARAMETROS!$B$7 -> 180 | J26: =IFERROR(SUMIFS(DIARIO!$D$2:$D$171,DIARIO!$B$2:$B$171,"MOVIL",DIARIO!$C$2:$C$171,$A26)/H26,0) -> 105089.98
A27: Search | B27: =SUMIFS(DIARIO!$F$2:$F$171,DIARIO!$B$2:$B$171,"MOVIL",DIARIO!$C$2:$C$171,$A27) -> 1968 | C27: =B27*PARAMETROS!$B$7 -> 7380 | D27: =IFERROR(SUMIFS(DIARIO!$D$2:$D$171,DIARIO!$B$2:$B$171,"MOVIL",DIARIO!$C$2:$C$171,$A27)/B27,0) -> 37462.047 | E27: =SUMIFS(DIARIO!$G$2:$G$171,DIARIO!$B$2:$B$171,"MOVIL",DIARIO!$C$2:$C$171,$A27) -> 875 | F27: =E27*PARAMETROS!$B$7 -> 3281.25 | G27: =IFERROR(SUMIFS(DIARIO!$D$2:$D$171,DIARIO!$B$2:$B$171,"MOVIL",DIARIO!$C$2:$C$171,$A27)/E27,0) -> 84257.495 | H27: =SUMIFS(DIARIO!$H$2:$H$171,DIARIO!$B$2:$B$171,"MOVIL",DIARIO!$C$2:$C$171,$A27) -> 796 | I27: =H27*PARAMETROS!$B$7 -> 2985 | J27: =IFERROR(SUMIFS(DIARIO!$D$2:$D$171,DIARIO!$B$2:$B$171,"MOVIL",DIARIO!$C$2:$C$171,$A27)/H27,0) -> 92619.734
A28: Search Mixto | B28: =SUMIFS(DIARIO!$F$2:$F$171,DIARIO!$B$2:$B$171,"MOVIL",DIARIO!$C$2:$C$171,$A28) -> 840 | C28: =B28*PARAMETROS!$B$7 -> 3150 | D28: =IFERROR(SUMIFS(DIARIO!$D$2:$D$171,DIARIO!$B$2:$B$171,"MOVIL",DIARIO!$C$2:$C$171,$A28)/B28,0) -> 11690.037 | E28: =SUMIFS(DIARIO!$G$2:$G$171,DIARIO!$B$2:$B$171,"MOVIL",DIARIO!$C$2:$C$171,$A28) -> 392.5 | F28: =E28*PARAMETROS!$B$7 -> 1471.875 | G28: =IFERROR(SUMIFS(DIARIO!$D$2:$D$171,DIARIO!$B$2:$B$171,"MOVIL",DIARIO!$C$2:$C$171,$A28)/E28,0) -> 25018.169 | H28: =SUMIFS(DIARIO!$H$2:$H$171,DIARIO!$B$2:$B$171,"MOVIL",DIARIO!$C$2:$C$171,$A28) -> 349 | I28: =H28*PARAMETROS!$B$7 -> 1308.75 | J28: =IFERROR(SUMIFS(DIARIO!$D$2:$D$171,DIARIO!$B$2:$B$171,"MOVIL",DIARIO!$C$2:$C$171,$A28)/H28,0) -> 28136.479
A29: TikTok | B29: =SUMIFS(DIARIO!$F$2:$F$171,DIARIO!$B$2:$B$171,"MOVIL",DIARIO!$C$2:$C$171,$A29) -> 48 | C29: =B29*PARAMETROS!$B$7 -> 180 | D29: =IFERROR(SUMIFS(DIARIO!$D$2:$D$171,DIARIO!$B$2:$B$171,"MOVIL",DIARIO!$C$2:$C$171,$A29)/B29,0) -> 0 | E29: =SUMIFS(DIARIO!$G$2:$G$171,DIARIO!$B$2:$B$171,"MOVIL",DIARIO!$C$2:$C$171,$A29) -> 3 | F29: =E29*PARAMETROS!$B$7 -> 11.25 | G29: =IFERROR(SUMIFS(DIARIO!$D$2:$D$171,DIARIO!$B$2:$B$171,"MOVIL",DIARIO!$C$2:$C$171,$A29)/E29,0) -> 0 | H29: =SUMIFS(DIARIO!$H$2:$H$171,DIARIO!$B$2:$B$171,"MOVIL",DIARIO!$C$2:$C$171,$A29) -> 2 | I29: =H29*PARAMETROS!$B$7 -> 7.5 | J29: =IFERROR(SUMIFS(DIARIO!$D$2:$D$171,DIARIO!$B$2:$B$171,"MOVIL",DIARIO!$C$2:$C$171,$A29)/H29,0) -> 0
A30: Total | B30: =SUM(B20:B29) -> 4420.5 | C30: =SUM(C20:C29) -> 16576.875 | D30: =IFERROR(SUMIFS(DIARIO!$D$2:$D$171,DIARIO!$B$2:$B$171,"MOVIL")/B30,0) -> 22638.091 | E30: =SUM(E20:E29) -> 1839 | F30: =SUM(F20:F29) -> 6896.25 | G30: =IFERROR(SUMIFS(DIARIO!$D$2:$D$171,DIARIO!$B$2:$B$171,"MOVIL")/E30,0) -> 54416.357 | H30: =SUM(H20:H29) -> 1584 | I30: =SUM(I20:I29) -> 5940 | J30: =IFERROR(SUMIFS(DIARIO!$D$2:$D$171,DIARIO!$B$2:$B$171,"MOVIL")/H30,0) -> 63176.566
A32: COSTOS FIJO | H32: LEADS FIJO | O32: CPL FIJO
A33: Canal 2 | B33: Meta Costo mes | C33: Meta a hoy | D33: Real Costo | E33: % a hoy | F33: Costo proyectado | H33: Canal 2 | I33: Meta Leads mes | J33: Meta a hoy | K33: Real Leads | L33: % a hoy | M33: Leads Proyectados | O33: Canal 2 | P33: CPL Meta | Q33: CPL | R33: % Cumplimiento
A34: *Sin Clasificar* | B34: =SUMIFS(METAS_DIA!$D$2:$D$541,METAS_DIA!$B$2:$B$541,"FIJO",METAS_DIA!$C$2:$C$541,$A34) -> 0 | C34: =SUMIFS(METAS_DIA!$D$2:$D$541,METAS_DIA!$B$2:$B$541,"FIJO",METAS_DIA!$C$2:$C$541,$A34,METAS_DIA!$A$2:$A$541,"<="&PARAMETROS!$B$9) -> 0 | D34: =SUMIFS(DIARIO!$D$2:$D$171,DIARIO!$B$2:$B$171,"FIJO",DIARIO!$C$2:$C$171,$A34) -> 0 | E34: =IFERROR(D34/C34,0) -> 0 | F34: =D34*PARAMETROS!$B$7 -> 0 | H34: *Sin Clasificar* | I34: =SUMIFS(METAS_DIA!$E$2:$E$541,METAS_DIA!$B$2:$B$541,"FIJO",METAS_DIA!$C$2:$C$541,$H34) -> 0 | J34: =SUMIFS(METAS_DIA!$E$2:$E$541,METAS_DIA!$B$2:$B$541,"FIJO",METAS_DIA!$C$2:$C$541,$H34,METAS_DIA!$A$2:$A$541,"<="&PARAMETROS!$B$9) -> 0 | K34: =SUMIFS(DIARIO!$E$2:$E$171,DIARIO!$B$2:$B$171,"FIJO",DIARIO!$C$2:$C$171,$H34) -> 0 | L34: =IFERROR(K34/J34,0) -> 0 | M34: =K34*PARAMETROS!$B$7 -> 0 | O34: *Sin Clasificar* | P34: =IFERROR(B34/I34,0) -> 0 | Q34: =IFERROR(D34/K34,0) -> 0 | R34: =IFERROR(Q34/P34,0) -> 0
A35: Afiliados | B35: =SUMIFS(METAS_DIA!$D$2:$D$541,METAS_DIA!$B$2:$B$541,"FIJO",METAS_DIA!$C$2:$C$541,$A35) -> 0 | C35: =SUMIFS(METAS_DIA!$D$2:$D$541,METAS_DIA!$B$2:$B$541,"FIJO",METAS_DIA!$C$2:$C$541,$A35,METAS_DIA!$A$2:$A$541,"<="&PARAMETROS!$B$9) -> 0 | D35: =SUMIFS(DIARIO!$D$2:$D$171,DIARIO!$B$2:$B$171,"FIJO",DIARIO!$C$2:$C$171,$A35) -> 0 | E35: =IFERROR(D35/C35,0) -> 0 | F35: =D35*PARAMETROS!$B$7 -> 0 | H35: Afiliados | I35: =SUMIFS(METAS_DIA!$E$2:$E$541,METAS_DIA!$B$2:$B$541,"FIJO",METAS_DIA!$C$2:$C$541,$H35) -> 0 | J35: =SUMIFS(METAS_DIA!$E$2:$E$541,METAS_DIA!$B$2:$B$541,"FIJO",METAS_DIA!$C$2:$C$541,$H35,METAS_DIA!$A$2:$A$541,"<="&PARAMETROS!$B$9) -> 0 | K35: =SUMIFS(DIARIO!$E$2:$E$171,DIARIO!$B$2:$B$171,"FIJO",DIARIO!$C$2:$C$171,$H35) -> 0 | L35: =IFERROR(K35/J35,0) -> 0 | M35: =K35*PARAMETROS!$B$7 -> 0 | O35: Afiliados | P35: =IFERROR(B35/I35,0) -> 0 | Q35: =IFERROR(D35/K35,0) -> 0 | R35: =IFERROR(Q35/P35,0) -> 0
A36: Bing | B36: =SUMIFS(METAS_DIA!$D$2:$D$541,METAS_DIA!$B$2:$B$541,"FIJO",METAS_DIA!$C$2:$C$541,$A36) -> 7000000 | C36: =SUMIFS(METAS_DIA!$D$2:$D$541,METAS_DIA!$B$2:$B$541,"FIJO",METAS_DIA!$C$2:$C$541,$A36,METAS_DIA!$A$2:$A$541,"<="&PARAMETROS!$B$9) -> 2092159 | D36: =SUMIFS(DIARIO!$D$2:$D$171,DIARIO!$B$2:$B$171,"FIJO",DIARIO!$C$2:$C$171,$A36) -> 1486993.7 | E36: =IFERROR(D36/C36,0) -> 0.71074603 | F36: =D36*PARAMETROS!$B$7 -> 5576226.4 | H36: Bing | I36: =SUMIFS(METAS_DIA!$E$2:$E$541,METAS_DIA!$B$2:$B$541,"FIJO",METAS_DIA!$C$2:$C$541,$H36) -> 875 | J36: =SUMIFS(METAS_DIA!$E$2:$E$541,METAS_DIA!$B$2:$B$541,"FIJO",METAS_DIA!$C$2:$C$541,$H36,METAS_DIA!$A$2:$A$541,"<="&PARAMETROS!$B$9) -> 261.51988 | K36: =SUMIFS(DIARIO!$E$2:$E$171,DIARIO!$B$2:$B$171,"FIJO",DIARIO!$C$2:$C$171,$H36) -> 197 | L36: =IFERROR(K36/J36,0) -> 0.75328882 | M36: =K36*PARAMETROS!$B$7 -> 738.75 | O36: Bing | P36: =IFERROR(B36/I36,0) -> 8000 | Q36: =IFERROR(D36/K36,0) -> 7548.1915 | R36: =IFERROR(Q36/P36,0) -> 0.94352393
A37: Bing Mixto | B37: =SUMIFS(METAS_DIA!$D$2:$D$541,METAS_DIA!$B$2:$B$541,"FIJO",METAS_DIA!$C$2:$C$541,$A37) -> 1000000 | C37: =SUMIFS(METAS_DIA!$D$2:$D$541,METAS_DIA!$B$2:$B$541,"FIJO",METAS_DIA!$C$2:$C$541,$A37,METAS_DIA!$A$2:$A$541,"<="&PARAMETROS!$B$9) -> 296000.09 | D37: =SUMIFS(DIARIO!$D$2:$D$171,DIARIO!$B$2:$B$171,"FIJO",DIARIO!$C$2:$C$171,$A37) -> 295353.35 | E37: =IFERROR(D37/C37,0) -> 0.99781506 | F37: =D37*PARAMETROS!$B$7 -> 1107575 | H37: Bing Mixto | I37: =SUMIFS(METAS_DIA!$E$2:$E$541,METAS_DIA!$B$2:$B$541,"FIJO",METAS_DIA!$C$2:$C$541,$H37) -> 83.333333 | J37: =SUMIFS(METAS_DIA!$E$2:$E$541,METAS_DIA!$B$2:$B$541,"FIJO",METAS_DIA!$C$2:$C$541,$H37,METAS_DIA!$A$2:$A$541,"<="&PARAMETROS!$B$9) -> 24.666674 | K37: =SUMIFS(DIARIO!$E$2:$E$171,DIARIO!$B$2:$B$171,"FIJO",DIARIO!$C$2:$C$171,$H37) -> 147.5 | L37: =IFERROR(K37/J37,0) -> 5.979728 | M37: =K37*PARAMETROS!$B$7 -> 553.125 | O37: Bing Mixto | P37: =IFERROR(B37/I37,0) -> 12000 | Q37: =IFERROR(D37/K37,0) -> 2002.3956 | R37: =IFERROR(Q37/P37,0) -> 0.1668663
A38: Meta | B38: =SUMIFS(METAS_DIA!$D$2:$D$541,METAS_DIA!$B$2:$B$541,"FIJO",METAS_DIA!$C$2:$C$541,$A38) -> 17320000 | C38: =SUMIFS(METAS_DIA!$D$2:$D$541,METAS_DIA!$B$2:$B$541,"FIJO",METAS_DIA!$C$2:$C$541,$A38,METAS_DIA!$A$2:$A$541,"<="&PARAMETROS!$B$9) -> 5176599.2 | D38: =SUMIFS(DIARIO!$D$2:$D$171,DIARIO!$B$2:$B$171,"FIJO",DIARIO!$C$2:$C$171,$A38) -> 6193479.3 | E38: =IFERROR(D38/C38,0) -> 1.1964379 | F38: =D38*PARAMETROS!$B$7 -> 23225548 | H38: Meta | I38: =SUMIFS(METAS_DIA!$E$2:$E$541,METAS_DIA!$B$2:$B$541,"FIJO",METAS_DIA!$C$2:$C$541,$H38) -> 1823.1579 | J38: =SUMIFS(METAS_DIA!$E$2:$E$541,METAS_DIA!$B$2:$B$541,"FIJO",METAS_DIA!$C$2:$C$541,$H38,METAS_DIA!$A$2:$A$541,"<="&PARAMETROS!$B$9) -> 544.90518 | K38: =SUMIFS(DIARIO!$E$2:$E$171,DIARIO!$B$2:$B$171,"FIJO",DIARIO!$C$2:$C$171,$H38) -> 730 | L38: =IFERROR(K38/J38,0) -> 1.3396826 | M38: =K38*PARAMETROS!$B$7 -> 2737.5 | O38: Meta | P38: =IFERROR(B38/I38,0) -> 9500 | Q38: =IFERROR(D38/K38,0) -> 8484.2183 | R38: =IFERROR(Q38/P38,0) -> 0.89307561
A39: Pmax | B39: =SUMIFS(METAS_DIA!$D$2:$D$541,METAS_DIA!$B$2:$B$541,"FIJO",METAS_DIA!$C$2:$C$541,$A39) -> 40000000 | C39: =SUMIFS(METAS_DIA!$D$2:$D$541,METAS_DIA!$B$2:$B$541,"FIJO",METAS_DIA!$C$2:$C$541,$A39,METAS_DIA!$A$2:$A$541,"<="&PARAMETROS!$B$9) -> 11955194 | D39: =SUMIFS(DIARIO!$D$2:$D$171,DIARIO!$B$2:$B$171,"FIJO",DIARIO!$C$2:$C$171,$A39) -> 12303805 | E39: =IFERROR(D39/C39,0) -> 1.0291598 | F39: =D39*PARAMETROS!$B$7 -> 46139269 | H39: Pmax | I39: =SUMIFS(METAS_DIA!$E$2:$E$541,METAS_DIA!$B$2:$B$541,"FIJO",METAS_DIA!$C$2:$C$541,$H39) -> 2666.6667 | J39: =SUMIFS(METAS_DIA!$E$2:$E$541,METAS_DIA!$B$2:$B$541,"FIJO",METAS_DIA!$C$2:$C$541,$H39,METAS_DIA!$A$2:$A$541,"<="&PARAMETROS!$B$9) -> 797.01296 | K39: =SUMIFS(DIARIO!$E$2:$E$171,DIARIO!$B$2:$B$171,"FIJO",DIARIO!$C$2:$C$171,$H39) -> 431 | L39: =IFERROR(K39/J39,0) -> 0.54076912 | M39: =K39*PARAMETROS!$B$7 -> 1616.25 | O39: Pmax | P39: =IFERROR(B39/I39,0) -> 15000 | Q39: =IFERROR(D39/K39,0) -> 28547.111 | R39: =IFERROR(Q39/P39,0) -> 1.9031408
A40: Pmax Mixto | B40: =SUMIFS(METAS_DIA!$D$2:$D$541,METAS_DIA!$B$2:$B$541,"FIJO",METAS_DIA!$C$2:$C$541,$A40) -> 9000000 | C40: =SUMIFS(METAS_DIA!$D$2:$D$541,METAS_DIA!$B$2:$B$541,"FIJO",METAS_DIA!$C$2:$C$541,$A40,METAS_DIA!$A$2:$A$541,"<="&PARAMETROS!$B$9) -> 2664000.8 | D40: =SUMIFS(DIARIO!$D$2:$D$171,DIARIO!$B$2:$B$171,"FIJO",DIARIO!$C$2:$C$171,$A40) -> 5044319.2 | E40: =IFERROR(D40/C40,0) -> 1.8935126 | F40: =D40*PARAMETROS!$B$7 -> 18916197 | H40: Pmax Mixto | I40: =SUMIFS(METAS_DIA!$E$2:$E$541,METAS_DIA!$B$2:$B$541,"FIJO",METAS_DIA!$C$2:$C$541,$H40) -> 1125 | J40: =SUMIFS(METAS_DIA!$E$2:$E$541,METAS_DIA!$B$2:$B$541,"FIJO",METAS_DIA!$C$2:$C$541,$H40,METAS_DIA!$A$2:$A$541,"<="&PARAMETROS!$B$9) -> 333.0001 | K40: =SUMIFS(DIARIO!$E$2:$E$171,DIARIO!$B$2:$B$171,"FIJO",DIARIO!$C$2:$C$171,$H40) -> 302 | L40: =IFERROR(K40/J40,0) -> 0.90690664 | M40: =K40*PARAMETROS!$B$7 -> 1132.5 | O40: Pmax Mixto | P40: =IFERROR(B40/I40,0) -> 8000 | Q40: =IFERROR(D40/K40,0) -> 16703.044 | R40: =IFERROR(Q40/P40,0) -> 2.0878804
A41: Search | B41: =SUMIFS(METAS_DIA!$D$2:$D$541,METAS_DIA!$B$2:$B$541,"FIJO",METAS_DIA!$C$2:$C$541,$A41) -> 2.4e+08 | C41: =SUMIFS(METAS_DIA!$D$2:$D$541,METAS_DIA!$B$2:$B$541,"FIJO",METAS_DIA!$C$2:$C$541,$A41,METAS_DIA!$A$2:$A$541,"<="&PARAMETROS!$B$9) -> 71731167 | D41: =SUMIFS(DIARIO!$D$2:$D$171,DIARIO!$B$2:$B$171,"FIJO",DIARIO!$C$2:$C$171,$A41) -> 54868487 | E41: =IFERROR(D41/C41,0) -> 0.76491837 | F41: =D41*PARAMETROS!$B$7 -> 2.0575683e+08 | H41: Search | I41: =SUMIFS(METAS_DIA!$E$2:$E$541,METAS_DIA!$B$2:$B$541,"FIJO",METAS_DIA!$C$2:$C$541,$H41) -> 12631.579 | J41: =SUMIFS(METAS_DIA!$E$2:$E$541,METAS_DIA!$B$2:$B$541,"FIJO",METAS_DIA!$C$2:$C$541,$H41,METAS_DIA!$A$2:$A$541,"<="&PARAMETROS!$B$9) -> 3775.3246 | K41: =SUMIFS(DIARIO!$E$2:$E$171,DIARIO!$B$2:$B$171,"FIJO",DIARIO!$C$2:$C$171,$H41) -> 1729 | L41: =IFERROR(K41/J41,0) -> 0.45797387 | M41: =K41*PARAMETROS!$B$7 -> 6483.75 | O41: Search | P41: =IFERROR(B41/I41,0) -> 19000 | Q41: =IFERROR(D41/K41,0) -> 31734.232 | R41: =IFERROR(Q41/P41,0) -> 1.6702227
A42: Search Mixto | B42: =SUMIFS(METAS_DIA!$D$2:$D$541,METAS_DIA!$B$2:$B$541,"FIJO",METAS_DIA!$C$2:$C$541,$A42) -> 50000000 | C42: =SUMIFS(METAS_DIA!$D$2:$D$541,METAS_DIA!$B$2:$B$541,"FIJO",METAS_DIA!$C$2:$C$541,$A42,METAS_DIA!$A$2:$A$541,"<="&PARAMETROS!$B$9) -> 14800004 | D42: =SUMIFS(DIARIO!$D$2:$D$171,DIARIO!$B$2:$B$171,"FIJO",DIARIO!$C$2:$C$171,$A42) -> 9819631.2 | E42: =IFERROR(D42/C42,0) -> 0.6634884 | F42: =D42*PARAMETROS!$B$7 -> 36823617 | H42: Search Mixto | I42: =SUMIFS(METAS_DIA!$E$2:$E$541,METAS_DIA!$B$2:$B$541,"FIJO",METAS_DIA!$C$2:$C$541,$H42) -> 9615.3846 | J42: =SUMIFS(METAS_DIA!$E$2:$E$541,METAS_DIA!$B$2:$B$541,"FIJO",METAS_DIA!$C$2:$C$541,$H42,METAS_DIA!$A$2:$A$541,"<="&PARAMETROS!$B$9) -> 2846.1547 | K42: =SUMIFS(DIARIO!$E$2:$E$171,DIARIO!$B$2:$B$171,"FIJO",DIARIO!$C$2:$C$171,$H42) -> 1024.5 | L42: =IFERROR(K42/J42,0) -> 0.35995935 | M42: =K42*PARAMETROS!$B$7 -> 3841.875 | O42: Search Mixto | P42: =IFERROR(B42/I42,0) -> 5200 | Q42: =IFERROR(D42/K42,0) -> 9584.8035 | R42: =IFERROR(Q42/P42,0) -> 1.8432314
A43: TikTok | B43: =SUMIFS(METAS_DIA!$D$2:$D$541,METAS_DIA!$B$2:$B$541,"FIJO",METAS_DIA!$C$2:$C$541,$A43) -> 0 | C43: =SUMIFS(METAS_DIA!$D$2:$D$541,METAS_DIA!$B$2:$B$541,"FIJO",METAS_DIA!$C$2:$C$541,$A43,METAS_DIA!$A$2:$A$541,"<="&PARAMETROS!$B$9) -> 0 | D43: =SUMIFS(DIARIO!$D$2:$D$171,DIARIO!$B$2:$B$171,"FIJO",DIARIO!$C$2:$C$171,$A43) -> 0 | E43: =IFERROR(D43/C43,0) -> 0 | F43: =D43*PARAMETROS!$B$7 -> 0 | H43: TikTok | I43: =SUMIFS(METAS_DIA!$E$2:$E$541,METAS_DIA!$B$2:$B$541,"FIJO",METAS_DIA!$C$2:$C$541,$H43) -> 0 | J43: =SUMIFS(METAS_DIA!$E$2:$E$541,METAS_DIA!$B$2:$B$541,"FIJO",METAS_DIA!$C$2:$C$541,$H43,METAS_DIA!$A$2:$A$541,"<="&PARAMETROS!$B$9) -> 0 | K43: =SUMIFS(DIARIO!$E$2:$E$171,DIARIO!$B$2:$B$171,"FIJO",DIARIO!$C$2:$C$171,$H43) -> 0 | L43: =IFERROR(K43/J43,0) -> 0 | M43: =K43*PARAMETROS!$B$7 -> 0 | O43: TikTok | P43: =IFERROR(B43/I43,0) -> 0 | Q43: =IFERROR(D43/K43,0) -> 0 | R43: =IFERROR(Q43/P43,0) -> 0
...

Sheet CURVA
A1: AVANCE DIARIO 2026-09 · Movil + Fijo (Mixto ya viene repartido)
A2: Fecha | B2: Meta Costo | C2: Costo | D2: % Costo | E2: Meta Lead | F2: Lead | G2: CPL | H2: Q Neto | I2: CPL Neto | J2: Q Emi | K2: CPE | L2: Q Ter | M2: CPA | N2: Costo acum | O2: Meta acum | P2: % acum
A3: 46266 | B3: =SUMIFS(METAS_DIA!$D$2:$D$541,METAS_DIA!$A$2:$A$541,$A3,METAS_DIA!$B$2:$B$541,"<>MIXTO") -> 27992912 | C3: =SUMIFS(DIARIO!$D$2:$D$171,DIARIO!$A$2:$A$171,$A3,DIARIO!$B$2:$B$171,"<>MIXTO") -> 24990256 | D3: =IFERROR(C3/B3,0) -> 0.89273511 | E3: =SUMIFS(METAS_DIA!$E$2:$E$541,METAS_DIA!$A$2:$A$541,$A3,METAS_DIA!$B$2:$B$541,"<>MIXTO") -> 2440.0235 | F3: =SUMIFS(DIARIO!$E$2:$E$171,DIARIO!$A$2:$A$171,$A3,DIARIO!$B$2:$B$171,"<>MIXTO") -> 1075 | G3: =IFERROR(C3/F3,0) -> 23246.749 | H3: =SUMIFS(DIARIO!$F$2:$F$171,DIARIO!$A$2:$A$171,$A3,DIARIO!$B$2:$B$171,"<>MIXTO") -> 991 | I3: =IFERROR($C3/H3,0) -> 25217.21 | J3: =SUMIFS(DIARIO!$G$2:$G$171,DIARIO!$A$2:$A$171,$A3,DIARIO!$B$2:$B$171,"<>MIXTO") -> 585 | K3: =IFERROR($C3/J3,0) -> 42718.386 | L3: =SUMIFS(DIARIO!$H$2:$H$171,DIARIO!$A$2:$A$171,$A3,DIARIO!$B$2:$B$171,"<>MIXTO") -> 554 | M3: =IFERROR($C3/L3,0) -> 45108.765 | N3: =SUM($C$3:C3) -> 24990256 | O3: =SUM($B$3:B3) -> 27992912 | P3: =IFERROR(N3/O3,0) -> 0.89273511
A4: 46267 | B4: =SUMIFS(METAS_DIA!$D$2:$D$541,METAS_DIA!$A$2:$A$541,$A4,METAS_DIA!$B$2:$B$541,"<>MIXTO") -> 25674562 | C4: =SUMIFS(DIARIO!$D$2:$D$171,DIARIO!$A$2:$A$171,$A4,DIARIO!$B$2:$B$171,"<>MIXTO") -> 25445742 | D4: =IFERROR(C4/B4,0) -> 0.99108768 | E4: =SUMIFS(METAS_DIA!$E$2:$E$541,METAS_DIA!$A$2:$A$541,$A4,METAS_DIA!$B$2:$B$541,"<>MIXTO") -> 2249.3882 | F4: =SUMIFS(DIARIO!$E$2:$E$171,DIARIO!$A$2:$A$171,$A4,DIARIO!$B$2:$B$171,"<>MIXTO") -> 1470 | G4: =IFERROR(C4/F4,0) -> 17310.028 | H4: =SUMIFS(DIARIO!$F$2:$F$171,DIARIO!$A$2:$A$171,$A4,DIARIO!$B$2:$B$171,"<>MIXTO") -> 1230 | I4: =IFERROR($C4/H4,0) -> 20687.595 | J4: =SUMIFS(DIARIO!$G$2:$G$171,DIARIO!$A$2:$A$171,$A4,DIARIO!$B$2:$B$171,"<>MIXTO") -> 596 | K4: =IFERROR($C4/J4,0) -> 42694.198 | L4: =SUMIFS(DIARIO!$H$2:$H$171,DIARIO!$A$2:$A$171,$A4,DIARIO!$B$2:$B$171,"<>MIXTO") -> 534 | M4: =IFERROR($C4/L4,0) -> 47651.202 | N4: =SUM($C$3:C4) -> 50435997 | O4: =SUM($B$3:B4) -> 53667474 | P4: =IFERROR(N4/O4,0) -> 0.93978706
A5: 46268 | B5: =SUMIFS(METAS_DIA!$D$2:$D$541,METAS_DIA!$A$2:$A$541,$A5,METAS_DIA!$B$2:$B$541,"<>MIXTO") -> 24248893 | C5: =SUMIFS(DIARIO!$D$2:$D$171,DIARIO!$A$2:$A$171,$A5,DIARIO!$B$2:$B$171,"<>MIXTO") -> 23523116 | D5: =IFERROR(C5/B5,0) -> 0.97006968 | E5: =SUMIFS(METAS_DIA!$E$2:$E$541,METAS_DIA!$A$2:$A$541,$A5,METAS_DIA!$B$2:$B$541,"<>MIXTO") -> 2113.3419 | F5: =SUMIFS(DIARIO!$E$2:$E$171,DIARIO!$A$2:$A$171,$A5,DIARIO!$B$2:$B$171,"<>MIXTO") -> 1470 | G5: =IFERROR(C5/F5,0) -> 16002.12 | H5: =SUMIFS(DIARIO!$F$2:$F$171,DIARIO!$A$2:$A$171,$A5,DIARIO!$B$2:$B$171,"<>MIXTO") -> 1113 | I5: =IFERROR($C5/H5,0) -> 21134.875 | J5: =SUMIFS(DIARIO!$G$2:$G$171,DIARIO!$A$2:$A$171,$A5,DIARIO!$B$2:$B$171,"<>MIXTO") -> 608 | K5: =IFERROR($C5/J5,0) -> 38689.336 | L5: =SUMIFS(DIARIO!$H$2:$H$171,DIARIO!$A$2:$A$171,$A5,DIARIO!$B$2:$B$171,"<>MIXTO") -> 469 | M5: =IFERROR($C5/L5,0) -> 50155.898 | N5: =SUM($C$3:C5) -> 73959114 | O5: =SUM($B$3:B5) -> 77916367 | P5: =IFERROR(N5/O5,0) -> 0.94921152
A6: 46269 | B6: =SUMIFS(METAS_DIA!$D$2:$D$541,METAS_DIA!$A$2:$A$541,$A6,METAS_DIA!$B$2:$B$541,"<>MIXTO") -> 22442933 | C6: =SUMIFS(DIARIO!$D$2:$D$171,DIARIO!$A$2:$A$171,$A6,DIARIO!$B$2:$B$171,"<>MIXTO") -> 22722906 | D6: =IFERROR(C6/B6,0) -> 1.0124749 | E6: =SUMIFS(METAS_DIA!$E$2:$E$541,METAS_DIA!$A$2:$A$541,$A6,METAS_DIA!$B$2:$B$541,"<>MIXTO") -> 1958.759 | F6: =SUMIFS(DIARIO!$E$2:$E$171,DIARIO!$A$2:$A$171,$A6,DIARIO!$B$2:$B$171,"<>MIXTO") -> 1300 | G6: =IFERROR(C6/F6,0) -> 17479.158 | H6: =SUMIFS(DIARIO!$F$2:$F$171,DIARIO!$A$2:$A$171,$A6,DIARIO!$B$2:$B$171,"<>MIXTO") -> 984 | I6: =IFERROR($C6/H6,0) -> 23092.384 | J6: =SUMIFS(DIARIO!$G$2:$G$171,DIARIO!$A$2:$A$171,$A6,DIARIO!$B$2:$B$171,"<>MIXTO") -> 482 | K6: =IFERROR($C6/J6,0) -> 47142.958 | L6: =SUMIFS(DIARIO!$H$2:$H$171,DIARIO!$A$2:$A$171,$A6,DIARIO!$B$2:$B$171,"<>MIXTO") -> 498 | M6: =IFERROR($C6/L6,0) -> 45628.325 | N6: =SUM($C$3:C6) -> 96682019 | O6: =SUM($B$3:B6) -> 1.003593e+08 | P6: =IFERROR(N6/O6,0) -> 0.96335885
A7: 46270 | B7: =SUMIFS(METAS_DIA!$D$2:$D$541,METAS_DIA!$A$2:$A$541,$A7,METAS_DIA!$B$2:$B$541,"<>MIXTO") -> 15425843 | C7: =SUMIFS(DIARIO!$D$2:$D$171,DIARIO!$A$2:$A$171,$A7,DIARIO!$B$2:$B$171,"<>MIXTO") -> 21181513 | D7: =IFERROR(C7/B7,0) -> 1.3731187 | E7: =SUMIFS(METAS_DIA!$E$2:$E$541,METAS_DIA!$A$2:$A$541,$A7,METAS_DIA!$B$2:$B$541,"<>MIXTO") -> 1342.8232 | F7: =SUMIFS(DIARIO!$E$2:$E$171,DIARIO!$A$2:$A$171,$A7,DIARIO!$B$2:$B$171,"<>MIXTO") -> 897 | G7: =IFERROR(C7/F7,0) -> 23613.727 | H7: =SUMIFS(DIARIO!$F$2:$F$171,DIARIO!$A$2:$A$171,$A7,DIARIO!$B$2:$B$171,"<>MIXTO") -> 610 | I7: =IFERROR($C7/H7,0) -> 34723.792 | J7: =SUMIFS(DIARIO!$G$2:$G$171,DIARIO!$A$2:$A$171,$A7,DIARIO!$B$2:$B$171,"<>MIXTO") -> 294 | K7: =IFERROR($C7/J7,0) -> 72045.964 | L7: =SUMIFS(DIARIO!$H$2:$H$171,DIARIO!$A$2:$A$171,$A7,DIARIO!$B$2:$B$171,"<>MIXTO") -> 379 | M7: =IFERROR($C7/L7,0) -> 55887.898 | N7: =SUM($C$3:C7) -> 1.1786353e+08 | O7: =SUM($B$3:B7) -> 1.1578514e+08 | P7: =IFERROR(N7/O7,0) -> 1.0179504
A8: 46271 | B8: =SUMIFS(METAS_DIA!$D$2:$D$541,METAS_DIA!$A$2:$A$541,$A8,METAS_DIA!$B$2:$B$541,"<>MIXTO") -> 14528466 | C8: =SUMIFS(DIARIO!$D$2:$D$171,DIARIO!$A$2:$A$171,$A8,DIARIO!$B$2:$B$171,"<>MIXTO") -> 17335465 | D8: =IFERROR(C8/B8,0) -> 1.1932069 | E8: =SUMIFS(METAS_DIA!$E$2:$E$541,METAS_DIA!$A$2:$A$541,$A8,METAS_DIA!$B$2:$B$541,"<>MIXTO") -> 1271.8347 | F8: =SUMIFS(DIARIO!$E$2:$E$171,DIARIO!$A$2:$A$171,$A8,DIARIO!$B$2:$B$171,"<>MIXTO") -> 840 | G8: =IFERROR(C8/F8,0) -> 20637.459 | H8: =SUMIFS(DIARIO!$F$2:$F$171,DIARIO!$A$2:$A$171,$A8,DIARIO!$B$2:$B$171,"<>MIXTO") -> 526 | I8: =IFERROR($C8/H8,0) -> 32957.158 | J8: =SUMIFS(DIARIO!$G$2:$G$171,DIARIO!$A$2:$A$171,$A8,DIARIO!$B$2:$B$171,"<>MIXTO") -> 251 | K8: =IFERROR($C8/J8,0) -> 69065.598 | L8: =SUMIFS(DIARIO!$H$2:$H$171,DIARIO!$A$2:$A$171,$A8,DIARIO!$B$2:$B$171,"<>MIXTO") -> 19 | M8: =IFERROR($C8/L8,0) -> 912392.91 | N8: =SUM($C$3:C8) -> 1.35199e+08 | O8: =SUM($B$3:B8) -> 1.3031361e+08 | P8: =IFERROR(N8/O8,0) -> 1.0374895
A9: 46272 | B9: =SUMIFS(METAS_DIA!$D$2:$D$541,METAS_DIA!$A$2:$A$541,$A9,METAS_DIA!$B$2:$B$541,"<>MIXTO") -> 32903880 | C9: =SUMIFS(DIARIO!$D$2:$D$171,DIARIO!$A$2:$A$171,$A9,DIARIO!$B$2:$B$171,"<>MIXTO") -> 28882765 | D9: =IFERROR(C9/B9,0) -> 0.87779208 | E9: =SUMIFS(METAS_DIA!$E$2:$E$541,METAS_DIA!$A$2:$A$541,$A9,METAS_DIA!$B$2:$B$541,"<>MIXTO") -> 2864.3612 | F9: =SUMIFS(DIARIO!$E$2:$E$171,DIARIO!$A$2:$A$171,$A9,DIARIO!$B$2:$B$171,"<>MIXTO") -> 1593 | G9: =IFERROR(C9/F9,0) -> 18131.052 | H9: =SUMIFS(DIARIO!$F$2:$F$171,DIARIO!$A$2:$A$171,$A9,DIARIO!$B$2:$B$171,"<>MIXTO") -> 1246 | I9: =IFERROR($C9/H9,0) -> 23180.389 | J9: =SUMIFS(DIARIO!$G$2:$G$171,DIARIO!$A$2:$A$171,$A9,DIARIO!$B$2:$B$171,"<>MIXTO") -> 653 | K9: =IFERROR($C9/J9,0) -> 44230.881 | L9: =SUMIFS(DIARIO!$H$2:$H$171,DIARIO!$A$2:$A$171,$A9,DIARIO!$B$2:$B$171,"<>MIXTO") -> 460 | M9: =IFERROR($C9/L9,0) -> 62788.62 | N9: =SUM($C$3:C9) -> 1.6408176e+08 | O9: =SUM($B$3:B9) -> 1.6321749e+08 | P9: =IFERROR(N9/O9,0) -> 1.0052952
A10: 46273 | B10: =SUMIFS(METAS_DIA!$D$2:$D$541,METAS_DIA!$A$2:$A$541,$A10,METAS_DIA!$B$2:$B$541,"<>MIXTO") -> 27656665 | C10: =SUMIFS(DIARIO!$D$2:$D$171,DIARIO!$A$2:$A$171,$A10,DIARIO!$B$2:$B$171,"<>MIXTO") -> 26001986 | D10: =IFERROR(C10/B10,0) -> 0.94017069 | E10: =SUMIFS(METAS_DIA!$E$2:$E$541,METAS_DIA!$A$2:$A$541,$A10,METAS_DIA!$B$2:$B$541,"<>MIXTO") -> 2408.2538 | F10: =SUMIFS(DIARIO!$E$2:$E$171,DIARIO!$A$2:$A$171,$A10,DIARIO!$B$2:$B$171,"<>MIXTO") -> 1446 | G10: =IFERROR(C10/F10,0) -> 17982.009 | H10: =SUMIFS(DIARIO!$F$2:$F$171,DIARIO!$A$2:$A$171,$A10,DIARIO!$B$2:$B$171,"<>MIXTO") -> 1302 | I10: =IFERROR($C10/H10,0) -> 19970.803 | J10: =SUMIFS(DIARIO!$G$2:$G$171,DIARIO!$A$2:$A$171,$A10,DIARIO!$B$2:$B$171,"<>MIXTO") -> 619 | K10: =IFERROR($C10/J10,0) -> 42006.439 | L10: =SUMIFS(DIARIO!$H$2:$H$171,DIARIO!$A$2:$A$171,$A10,DIARIO!$B$2:$B$171,"<>MIXTO") -> 512 | M10: =IFERROR($C10/L10,0) -> 50785.128 | N10: =SUM($C$3:C10) -> 1.9008375e+08 | O10: =SUM($B$3:B10) -> 1.9087415e+08 | P10: =IFERROR(N10/O10,0) -> 0.99585903
A11: 46274 | B11: =SUMIFS(METAS_DIA!$D$2:$D$541,METAS_DIA!$A$2:$A$541,$A11,METAS_DIA!$B$2:$B$541,"<>MIXTO") -> 25195650 | C11: =SUMIFS(DIARIO!$D$2:$D$171,DIARIO!$A$2:$A$171,$A11,DIARIO!$B$2:$B$171,"<>MIXTO") -> 0 | D11: =IFERROR(C11/B11,0) -> 0 | E11: =SUMIFS(METAS_DIA!$E$2:$E$541,METAS_DIA!$A$2:$A$541,$A11,METAS_DIA!$B$2:$B$541,"<>MIXTO") -> 2203.4029 | F11: =SUMIFS(DIARIO!$E$2:$E$171,DIARIO!$A$2:$A$171,$A11,DIARIO!$B$2:$B$171,"<>MIXTO") -> 0 | G11: =IFERROR(C11/F11,0) -> 0 | H11: =SUMIFS(DIARIO!$F$2:$F$171,DIARIO!$A$2:$A$171,$A11,DIARIO!$B$2:$B$171,"<>MIXTO") -> 0 | I11: =IFERROR($C11/H11,0) -> 0 | J11: =SUMIFS(DIARIO!$G$2:$G$171,DIARIO!$A$2:$A$171,$A11,DIARIO!$B$2:$B$171,"<>MIXTO") -> 0 | K11: =IFERROR($C11/J11,0) -> 0 | L11: =SUMIFS(DIARIO!$H$2:$H$171,DIARIO!$A$2:$A$171,$A11,DIARIO!$B$2:$B$171,"<>MIXTO") -> 0 | M11: =IFERROR($C11/L11,0) -> 0 | N11: =SUM($C$3:C11) -> 1.9008375e+08 | O11: =SUM($B$3:B11) -> 2.160698e+08 | P11: =IFERROR(N11/O11,0) -> 0.87973306
A12: 46275 | B12: =SUMIFS(METAS_DIA!$D$2:$D$541,METAS_DIA!$A$2:$A$541,$A12,METAS_DIA!$B$2:$B$541,"<>MIXTO") -> 23981946 | C12: =SUMIFS(DIARIO!$D$2:$D$171,DIARIO!$A$2:$A$171,$A12,DIARIO!$B$2:$B$171,"<>MIXTO") -> 0 | D12: =IFERROR(C12/B12,0) -> 0 | E12: =SUMIFS(METAS_DIA!$E$2:$E$541,METAS_DIA!$A$2:$A$541,$A12,METAS_DIA!$B$2:$B$541,"<>MIXTO") -> 2088.0884 | F12: =SUMIFS(DIARIO!$E$2:$E$171,DIARIO!$A$2:$A$171,$A12,DIARIO!$B$2:$B$171,"<>MIXTO") -> 0 | G12: =IFERROR(C12/F12,0) -> 0 | H12: =SUMIFS(DIARIO!$F$2:$F$171,DIARIO!$A$2:$A$171,$A12,DIARIO!$B$2:$B$171,"<>MIXTO") -> 0 | I12: =IFERROR($C12/H12,0) -> 0 | J12: =SUMIFS(DIARIO!$G$2:$G$171,DIARIO!$A$2:$A$171,$A12,DIARIO!$B$2:$B$171,"<>MIXTO") -> 0 | K12: =IFERROR($C12/J12,0) -> 0 | L12: =SUMIFS(DIARIO!$H$2:$H$171,DIARIO!$A$2:$A$171,$A12,DIARIO!$B$2:$B$171,"<>MIXTO") -> 0 | M12: =IFERROR($C12/L12,0) -> 0 | N12: =SUM($C$3:C12) -> 1.9008375e+08 | O12: =SUM($B$3:B12) -> 2.4005175e+08 | P12: =IFERROR(N12/O12,0) -> 0.79184488
A13: 46276 | B13: =SUMIFS(METAS_DIA!$D$2:$D$541,METAS_DIA!$A$2:$A$541,$A13,METAS_DIA!$B$2:$B$541,"<>MIXTO") -> 22112148 | C13: =SUMIFS(DIARIO!$D$2:$D$171,DIARIO!$A$2:$A$171,$A13,DIARIO!$B$2:$B$171,"<>MIXTO") -> 0 | D13: =IFERROR(C13/B13,0) -> 0 | E13: =SUMIFS(METAS_DIA!$E$2:$E$541,METAS_DIA!$A$2:$A$541,$A13,METAS_DIA!$B$2:$B$541,"<>MIXTO") -> 1927.2491 | F13: =SUMIFS(DIARIO!$E$2:$E$171,DIARIO!$A$2:$A$171,$A13,DIARIO!$B$2:$B$171,"<>MIXTO") -> 0 | G13: =IFERROR(C13/F13,0) -> 0 | H13: =SUMIFS(DIARIO!$F$2:$F$171,DIARIO!$A$2:$A$171,$A13,DIARIO!$B$2:$B$171,"<>MIXTO") -> 0 | I13: =IFERROR($C13/H13,0) -> 0 | J13: =SUMIFS(DIARIO!$G$2:$G$171,DIARIO!$A$2:$A$171,$A13,DIARIO!$B$2:$B$171,"<>MIXTO") -> 0 | K13: =IFERROR($C13/J13,0) -> 0 | L13: =SUMIFS(DIARIO!$H$2:$H$171,DIARIO!$A$2:$A$171,$A13,DIARIO!$B$2:$B$171,"<>MIXTO") -> 0 | M13: =IFERROR($C13/L13,0) -> 0 | N13: =SUM($C$3:C13) -> 1.9008375e+08 | O13: =SUM($B$3:B13) -> 2.621639e+08 | P13: =IFERROR(N13/O13,0) -> 0.72505692
A14: 46277 | B14: =SUMIFS(METAS_DIA!$D$2:$D$541,METAS_DIA!$A$2:$A$541,$A14,METAS_DIA!$B$2:$B$541,"<>MIXTO") -> 15202280 | C14: =SUMIFS(DIARIO!$D$2:$D$171,DIARIO!$A$2:$A$171,$A14,DIARIO!$B$2:$B$171,"<>MIXTO") -> 0 | D14: =IFERROR(C14/B14,0) -> 0 | E14: =SUMIFS(METAS_DIA!$E$2:$E$541,METAS_DIA!$A$2:$A$541,$A14,METAS_DIA!$B$2:$B$541,"<>MIXTO") -> 1321.5187 | F14: =SUMIFS(DIARIO!$E$2:$E$171,DIARIO!$A$2:$A$171,$A14,DIARIO!$B$2:$B$171,"<>MIXTO") -> 0 | G14: =IFERROR(C14/F14,0) -> 0 | H14: =SUMIFS(DIARIO!$F$2:$F$171,DIARIO!$A$2:$A$171,$A14,DIARIO!$B$2:$B$171,"<>MIXTO") -> 0 | I14: =IFERROR($C14/H14,0) -> 0 | J14: =SUMIFS(DIARIO!$G$2:$G$171,DIARIO!$A$2:$A$171,$A14,DIARIO!$B$2:$B$171,"<>MIXTO") -> 0 | K14: =IFERROR($C14/J14,0) -> 0 | L14: =SUMIFS(DIARIO!$H$2:$H$171,DIARIO!$A$2:$A$171,$A14,DIARIO!$B$2:$B$171,"<>MIXTO") -> 0 | M14: =IFERROR($C14/L14,0) -> 0 | N14: =SUM($C$3:C14) -> 1.9008375e+08 | O14: =SUM($B$3:B14) -> 2.7736618e+08 | P14: =IFERROR(N14/O14,0) -> 0.68531697
... A32: 46295 | B32: =SUMIFS(METAS_DIA!$D$2:$D$541,METAS_DIA!$A$2:$A$541,$A32,METAS_DIA!$B$2:$B$541,"<>MIXTO") -> 25046346 | C32: =SUMIFS(DIARIO!$D$2:$D$171,DIARIO!$A$2:$A$171,$A32,DIARIO!$B$2:$B$171,"<>MIXTO") -> 0 | D32: =IFERROR(C32/B32,0) -> 0 | E32: =SUMIFS(METAS_DIA!$E$2:$E$541,METAS_DIA!$A$2:$A$541,$A32,METAS_DIA!$B$2:$B$541,"<>MIXTO") -> 2183.3195 | F32: =SUMIFS(DIARIO!$E$2:$E$171,DIARIO!$A$2:$A$171,$A32,DIARIO!$B$2:$B$171,"<>MIXTO") -> 0 | G32: =IFERROR(C32/F32,0) -> 0 | H32: =SUMIFS(DIARIO!$F$2:$F$171,DIARIO!$A$2:$A$171,$A32,DIARIO!$B$2:$B$171,"<>MIXTO") -> 0 | I32: =IFERROR($C32/H32,0) -> 0 | J32: =SUMIFS(DIARIO!$G$2:$G$171,DIARIO!$A$2:$A$171,$A32,DIARIO!$B$2:$B$171,"<>MIXTO") -> 0 | K32: =IFERROR($C32/J32,0) -> 0 | L32: =SUMIFS(DIARIO!$H$2:$H$171,DIARIO!$A$2:$A$171,$A32,DIARIO!$B$2:$B$171,"<>MIXTO") -> 0 | M32: =IFERROR($C32/L32,0) -> 0 | N32: =SUM($C$3:C32) -> 1.9008375e+08 | O32: =SUM($B$3:B32) -> 6.4402167e+08 | P32: =IFERROR(N32/O32,0) -> 0.29515117
A33: TOTAL MES | B33: =SUM(B3:B32) -> 6.4402167e+08 | C33: =SUM(C3:C32) -> 1.9008375e+08 | D33: =IFERROR(C33/B33,0) -> 0.29515117 | E33: =SUM(E3:E32) -> 56232.182 | F33: =SUM(F3:F32) -> 10091 | G33: =IFERROR(C33/F33,0) -> 18836.959 | H33: =SUM(H3:H32) -> 8002 | I33: =IFERROR($C33/H33,0) -> 23754.53 | J33: =SUM(J3:J32) -> 4088 | K33: =IFERROR($C33/J33,0) -> 46497.982 | L33: =SUM(L3:L32) -> 3425 | M33: =IFERROR($C33/L33,0) -> 55498.905
A34: PROYECTADO A CIERRE | B34: =B33 -> 6.4402167e+08 | C34: =C33*PARAMETROS!$B$7 -> 7.1281406e+08 | D34: =IFERROR(C34/B34,0) -> 1.1068169 | E34: =E33 -> 56232.182 | F34: =F33*PARAMETROS!$B$7 -> 37841.25 | G34: =IFERROR(C34/F34,0) -> 18836.959 | H34: =H33*PARAMETROS!$B$7 -> 30007.5 | I34: =IFERROR($C34/H34,0) -> 23754.53 | J34: =J33*PARAMETROS!$B$7 -> 15330 | K34: =IFERROR($C34/J34,0) -> 46497.982 | L34: =L33*PARAMETROS!$B$7 -> 12843.75 | M34: =IFERROR($C34/L34,0) -> 55498.905

Sheet CONTROL
A1: CONTROL DE CRUCE REAL vs PPTO
A2: Revisa esta hoja cada mes. Si aparece algo, es que cambio el nombre de un canal o que falta cargarlo en el PPTo.
A4: BLOQUE | B4: CANAL 2 | C4: SITUACION | D4: ACCION SUGERIDA
A5: FIJO | B5: *Sin Clasificar* | C5: Tiene inversion real pero no tiene meta en el PPTo | D5: Cargar la meta o confirmar que no lleva
A6: FIJO | B6: Afiliados | C6: Tiene inversion real pero no tiene meta en el PPTo | D6: Cargar la meta o confirmar que no lleva
A7: FIJO | B7: TikTok | C7: Tiene inversion real pero no tiene meta en el PPTo | D7: Cargar la meta o confirmar que no lleva
A8: MOVIL | B8: Afiliados | C8: Tiene inversion real pero no tiene meta en el PPTo | D8: Cargar la meta o confirmar que no lleva
A9: MOVIL | B9: TikTok | C9: Tiene inversion real pero no tiene meta en el PPTo | D9: Cargar la meta o confirmar que no lleva
A10: MOVIL | B10: Display | C10: Tiene meta pero todavia no registra inversion | D10: Verificar si la campana ya arranco

Sheet PARAMETROS
A1: PARAMETROS DEL TRACKING
A3: Mes reportado | B3: 2026-09
A4: Area | B4: CANAL ONLINE
A5: Dias con informacion | B5: 8 | C5: Bajalo si el ultimo dia viene incompleto
A6: Dias del mes | B6: 30
A7: Factor de proyeccion | B7: =B6/B5 -> 3.75 | C7: Real acumulado x este factor = proyectado a cierre
A8: % de MIXTO asignado a Movil y a Fijo | B8: 0.5
A9: Ultima fecha con datos reales | B9: 46273

Sheet DIARIO
A1: FECHA | B1: BLOQUE | C1: CANAL 2 | D1: COSTO | E1: LEADS | F1: Q NETO | G1: Q EMI | H1: Q TER
A2: 46266 | B2: FIJO | C2: *Sin Clasificar* | D2: 0 | E2: 0 | F2: 3 | G2: 0 | H2: 0
A3: 46266 | B3: FIJO | C3: Afiliados | D3: 0 | E3: 0 | F3: 99 | G3: 63 | H3: 28
A4: 46266 | B4: FIJO | C4: Bing | D4: 221447.63 | E4: 31 | F4: 4 | G4: 6 | H4: 7
A5: 46266 | B5: FIJO | C5: Bing Mixto | D5: 37640.802 | E5: 28.5 | F5: 9.5 | G5: 5 | H5: 1
A6: 46266 | B6: FIJO | C6: Meta | D6: 1038708.4 | E6: 122 | F6: 45 | G6: 31 | H6: 24
A7: 46266 | B7: FIJO | C7: Pmax | D7: 2312273.1 | E7: 111 | F7: 97 | G7: 87 | H7: 22
A8: 46266 | B8: FIJO | C8: Pmax Mixto | D8: 0 | E8: 0 | F8: 0.5 | G8: 0 | H8: 6
A9: 46266 | B9: FIJO | C9: Search | D9: 11648697 | E9: 209 | F9: 174 | G9: 146 | H9: 150
A10: 46266 | B10: FIJO | C10: Search Mixto | D10: 0 | E10: 0 | F10: 5 | G10: 15 | H10: 61.5
A11: 46266 | B11: FIJO | C11: TikTok | D11: 0 | E11: 0 | F11: 6 | G11: 0 | H11: 0
A12: 46266 | B12: MIXTO | C12: Bing Mixto | D12: 75281.604 | E12: 57 | F12: 19 | G12: 10 | H12: 2
A13: 46266 | B13: MIXTO | C13: Pmax Mixto | D13: 0 | E13: 0 | F13: 1 | G13: 0 | H13: 12
... A171: 46273 | B171: MOVIL | C171: TikTok | D171: 0 | E171: 0 | F171: 16 | G171: 0 | H171: 0

Sheet METAS_DIA
A1: FECHA | B1: BLOQUE | C1: CANAL 2 | D1: META COSTO | E1: META LEADS | F1: META VENTAS
A2: 46266 | B2: FIJO | C2: Bing | D2: 308482.74 | E2: 38.560343 | F2: 3.8560343
A3: 46266 | B3: FIJO | C3: Bing Mixto | D3: 43374.553 | E3: 3.6145461 | F3: 0
A4: 46266 | B4: FIJO | C4: Meta | D4: 763274.45 | E4: 80.344679 | F4: 8.4808272
A5: 46266 | B5: FIJO | C5: Pmax | D5: 1762758.5 | E5: 117.51724 | F5: 17.627585
A6: 46266 | B6: FIJO | C6: Pmax Mixto | D6: 390370.98 | E6: 48.796373 | F6: 0
A7: 46266 | B7: FIJO | C7: Search | D7: 10576551 | E7: 556.66059 | F7: 162.71617
A8: 46266 | B8: FIJO | C8: Search Mixto | D8: 2168727.7 | E8: 417.06301 | F8: 0
A9: 46266 | B9: MIXTO | C9: Bing Mixto | D9: 86749.107 | E9: 7.2290922 | F9: 0
A10: 46266 | B10: MIXTO | C10: Pmax Mixto | D10: 780741.96 | E10: 97.592745 | F10: 0
A11: 46266 | B11: MIXTO | C11: Search Mixto | D11: 4337455.3 | E11: 834.12603 | F11: 0
A12: 46266 | B12: MOVIL | C12: Bing | D12: 213400.72 | E12: 30.485817 | F12: 0
A13: 46266 | B13: MOVIL | C13: Bing Mixto | D13: 43374.553 | E13: 3.6145461 | F13: 0
... A541: 46295 | B541: MOVIL | C541: Search Mixto | D541: 1940593.9 | E541: 373.19113 | F541: 0
